Workbook

Sheet 2026
A1: Setor (Cod) | B1: Setor | C1: Emenda | D1: Emenda (Modalidade) | E1: Emenda (Tipo) | F1: Autor (Cod) | G1: Autor | H1: Autor (Tipo) | I1: Autor (UF) | J1: Partido | K1: Órgão (Cod) | L1: Órgão | M1: UO (Cod) | N1: UO | O1: Funcional | P1: Função | Q1: Subfunção | R1: Programa | S1: Ação | T1: Subtítulo | U1: UF | V1: Localidade | W1: Esfera (Cod) | X1: GND (Cod) | Y1: Mod. Aplic. (Cod) | Z1: ID Uso (Cod) | AA1: Identificador Primário (Cod) | AB1: Fonte (Cod) | AC1: Valor Solicitado | AD1: Emenda (Justificativa) | AE1: OM | AF1: Objeto
A2: 13 | B2: DEFESA | C2: 12700001 | D2: INDIVIDUAL | E2: INCLUSÃO - APROPRIAÇÃO | F2: 1270 | G2: JOÃO CARLOS BACELAR | H2: DEPUTADO FEDERAL | I2: BA | J2: PL | K2: 52000 | L2: MINISTÉRIO DA DEFESA | M2: 52121 | N2: COMANDO DO EXÉRCITO | O2: 05.122.0032.2000.0029 | P2: DEFESA NACIONAL | Q2: ADMINISTRAÇÃO GERAL | R2: PROGRAMA DE GESTÃO E MANUTENÇÃO DO PODER EXECUTIVO | S2: ADMINISTRAÇÃO DA UNIDADE | T2: NO ESTADO DA BAHIA | U2: BA | V2: BAHIA | W2: F | X2: 4 | Y2: 90 | Z2: 0 | AA2: 6 | AB2: 1000 | AC2: 250000 | AD2: MELHORAR A ESTRUTURA DOS SETORES EDUCACIONAIS E ADMINISTRATIVOS, PROPORCIONANDO MAIOR EFETIVIDADE NA EXECUÇÃO DOS PROCESSOS | AE2: Colégio Militar de Salvador | AF2: Material permanente
A3: 13 | B3: DEFESA | C3: 12700002 | D3: INDIVIDUAL | E3: INCLUSÃO - APROPRIAÇÃO | F3: 1270 | G3: JOÃO CARLOS BACELAR | H3: DEPUTADO FEDERAL | I3: BA | J3: PL | K3: 52000 | L3: MINISTÉRIO DA DEFESA | M3: 52131 | N3: COMANDO DA MARINHA | O3: 05.152.6112.219D.0029 | P3: DEFESA NACIONAL | Q3: DEFESA NAVAL | R3: DEFESA NACIONAL | S3: ADEQUAÇÃO DE ATIVOS DE INFRAESTRUTURA DAS ORGANIZAÇÕES MILITARES | T3: NO ESTADO DA BAHIA | U3: BA | V3: BAHIA | W3: F | X3: 4 | Y3: 90 | Z3: 0 | AA3: 6 | AB3: 1000 | AC3: 150000 | AD3: ESTA PROPOSTA DE EMENDA VISA A AQUISIÇÃO DE EQUIPAMENTOS E EXECUÇÃO DE OBRAS NECESSÁRIAS A REVITALIZAÇÃO E ADEQUAÇÃO DA INFRAESTRUTURA DA DELEGACIA DA CAPITANIA DOS PORTOS EM PORTO SEGURO.
A4: 13 | B4: DEFESA | C4: 12770013 | D4: INDIVIDUAL | E4: INCLUSÃO - APROPRIAÇÃO | F4: 1277 | G4: WELLINGTON ROBERTO | H4: DEPUTADO FEDERAL | I4: PB | J4: PSD | K4: 52000 | L4: MINISTÉRIO DA DEFESA | M4: 52931 | N4: FUNDO NAVAL | O4: 05.125.6112.21BY.0001 | P4: DEFESA NACIONAL | Q4: NORMATIZAÇÃO E FISCALIZAÇÃO | R4: DEFESA NACIONAL | S4: FISCALIZAÇÃO DA NAVEGAÇÃO AQUAVIÁRIA | T4: NACIONAL | U4: NA | V4: NACIONAL | W4: F | X4: 4 | Y4: 90 | Z4: 0 | AA4: 6 | AB4: 1000 | AC4: 100000 | AD4: RECURSOS PARA DAR CONTINUIDADE NO PROCESSO DE AUMENTO DAS CAPACIDADES OPERACIONAIS DA CAPITANIA.
A5: 13 | B5: DEFESA | C5: 14510005 | D5: INDIVIDUAL | E5: INCLUSÃO - APROPRIAÇÃO | F5: 1451 | G5: VANDER LOUBET | H5: DEPUTADO FEDERAL | I5: MS | J5: PT | K5: 52000 | L5: MINISTÉRIO DA DEFESA | M5: 52121 | N5: COMANDO DO EXÉRCITO | O5: 05.153.6112.21A0.5218 | P5: DEFESA NACIONAL | Q5: DEFESA TERRESTRE | R5: DEFESA NACIONAL | S5: APRESTAMENTO DAS FORÇAS - MANUTENÇÃO DA PRONTIDÃO E DA CAPACIDADE OPERATIVA | T5: NO MUNICÍPIO DE CAMPO GRANDE - MS | U5: MS | V5: CAMPO GRANDE | W5: F | X5: 4 | Y5: 90 | Z5: 0 | AA5: 6 | AB5: 1000 | AC5: 500000 | AD5: APRESTAMENTO DAS FORÇAS - MANUTENÇÃO DA PRONTIDÃO E DA CAPACIDADE OPERATIVA - ADEQUAÇÃO DAS INSTALAÇÕES PARA O SERVIÇO MILITAR FEMININO DM CAMPO GRANDE - MS. | AE5: Cmdo 9ª RM | AF5: Mobiliário para o SMIF
A6: 13 | B6: DEFESA | C6: 14510009 | D6: INDIVIDUAL | E6: ACRÉSCIMO - APROPRIAÇÃO | F6: 1451 | G6: VANDER LOUBET | H6: DEPUTADO FEDERAL | I6: MS | J6: PT | K6: 52000 | L6: MINISTÉRIO DA DEFESA | M6: 52931 | N6: FUNDO NAVAL | O6: 05.152.6112.21A0.0001 | P6: DEFESA NACIONAL | Q6: DEFESA NAVAL | R6: DEFESA NACIONAL | S6: APRESTAMENTO DAS FORÇAS - MANUTENÇÃO DA PRONTIDÃO E DA CAPACIDADE OPERATIVA | T6: NACIONAL | U6: NA | V6: NACIONAL | W6: F | X6: 4 | Y6: 90 | Z6: 0 | AA6: 6 | AB6: 1000 | AC6: 300000 | AD6: AGÊNCIA FLUVIAL DE PORTO MURTINHO_x000D_ CNPJ: 00.394.502/0365-05_x000D_ _x000D_ MODERNIZAÇÃO DO PARQUE DE INFORMÁTICA E AQUISIÇÃO DE ITENS DE MOBILIÁRIO DA AGÊNCIA FLUVIAL DE PORTO MURTINHO, A FIM DE PROPORCIONAR EFICIÊNCIA E CELERIDADE AO ATENDIMENTO AOS CIDADÃOS SUL MATO-GROSSENSES QUE BUSCAM OS SERVIÇOS OFERECIDOS PELA AGÊNCIA.
A7: 13 | B7: DEFESA | C7: 15270016 | D7: INDIVIDUAL | E7: INCLUSÃO - APROPRIAÇÃO | F7: 1527 | G7: CARLOS SAMPAIO | H7: DEPUTADO FEDERAL | I7: SP | J7: PSD | K7: 52000 | L7: MINISTÉRIO DA DEFESA | M7: 52111 | N7: COMANDO DA AERONÁUTICA | O7: 05.122.0032.2000.0035 | P7: DEFESA NACIONAL | Q7: ADMINISTRAÇÃO GERAL | R7: PROGRAMA DE GESTÃO E MANUTENÇÃO DO PODER EXECUTIVO | S7: ADMINISTRAÇÃO DA UNIDADE | T7: NO ESTADO DE SÃO PAULO | U7: SP | V7: SÃO PAULO | W7: F | X7: 3 | Y7: 90 | Z7: 0 | AA7: 6 | AB7: 1000 | AC7: 300000 | AD7: A FORÇA AÉAREA BRASILEIRA (FAB), COMO INSTITUIÇÃO DE ESTADO, ATUA, INITERRUPTAMENTE, NA DEFESA DA PÁTRIA, NA MANUTENÇÃO DA SOBERANIA DO NOSSO ESPAÇO AÉREO, NA PROTEÇÃO DE NOSSAS FRONTEIRAS E NA INTEGRAÇÃO DO TERRITÓRIO NACIONAL._x000D_ ADEMAIS, SUBSIDIARIAMENTE, A FAB CUMPRE MISSÕES HUMANITÁRIAS E REPATRIAÇÃO DE NACIONAIS, DE TRANSPORTE DE ÓRGÃOS E TECIDOS, BEM COMO CONTRIBUI COM O DESENVOLVIMENTO TECNOLÓGICO, GERANDO EMPREGOS E RIQUEZAS AO PAÍS._x000D_ PELO EXPOSTO, PARA CONTRIBUIR COM A FAB NO CUMPRIMENTO DE SUA MISSÃO CONSTITUCIONAL EM BENEFÍCIO DA SOCIEDADE BRASILEIRA, É NECESSÁRIO O APOIO AOS PROJETOS E ATIVIDADES MENCIONADOS A SEGUIR COM O APORTE DE RECURSOS DE EMENDAS PARLAMENTARES NA LEI ORÇAMENTÁRIA ANUAL (LOA) DE 2026._x000D_ _x000D_ OM BENEFICIADA: ESQUADRÃO DE DEMONSTRAÇÃO AÉREA_x000D_ OBJETO RESUMIDO: READEQUAÇÃO DA INFRAESTRUTURA DO HANGAR DA ESQUADRILHA DA FUMAÇA.
A8: 13 | B8: DEFESA | C8: 15680002 | D8: INDIVIDUAL | E8: INCLUSÃO - APROPRIAÇÃO | F8: 1568 | G8: GILBERTO NASCIMENTO | H8: DEPUTADO FEDERAL | I8: SP | J8: PODE | K8: 52000 | L8: MINISTÉRIO DA DEFESA | M8: 52111 | N8: COMANDO DA AERONÁUTICA | O8: 05.301.0032.2E74.0035 | P8: DEFESA NACIONAL | Q8: ATENÇÃO BÁSICA | R8: PROGRAMA DE GESTÃO E MANUTENÇÃO DO PODER EXECUTIVO | S8: ESTRUTURAÇÃO E MODERNIZAÇÃO DE UNIDADES DE SAÚDE DAS FORÇAS ARMADAS | T8: NO ESTADO DE SÃO PAULO | U8: SP | V8: SÃO PAULO | W8: S | X8: 4 | Y8: 90 | Z8: 0 | AA8: 6 | AB8: 1000 | AC8: 450000 | AD8: CNPJ PARA LANÇAMENTO NO SIOP: 00.394.429/0001-00 - COMANDO DA AERONÁUTICA_x000D_ OM BENEFICIADA: HOSPITAL DE FORÇA AÉREA DE SÃO PAULO_x000D_ OBJETO RESUMIDO: AQUISIÇÃO DE CENTRAL DE INCLUSÃO HISTOLÓGICA E IMPRESSORA DE CASSETES HISTOLÓGICOS._x000D_ JUSTIFICATIVA:_x000D_ A FORÇA AÉREA BRASILEIRA (FAB), COMO INSTITUIÇÃO DE ESTADO, ATUA, ININTERRUPTAMENTE, NA DEFESA DA PÁTRIA, NA MANUTENÇÃO DA SOBERANIA DO NOSSO ESPAÇO AÉREO, NA PROTEÇÃO DE NOSSAS FRONTEIRAS E NA INTEGRAÇÃO DO TERRITÓRIO NACIONAL._x000D_ ADEMAIS, SUBSIDIARIAMENTE, A FAB CUMPRE MISSÕES HUMANITÁRIAS E DE REPATRIAÇÃO DE NACIONAIS, DE TRANSPORTE DE ÓRGÃOS E TECIDOS, BEM COMO CONTRIBUI COM O DESENVOLVIMENTO TECNOLÓGICO, GERANDO EMPREGOS E RIQUEZAS AO PAÍS._x000D_ PELO EXPOSTO, PARA CONTRIBUIR COM A FAB NO CUMPRIMENTO DE SUA MISSÃO CONSTITUCIONAL EM BENEFÍCIO DA SOCIEDADE BRASILEIRA, É NECESSÁRIO O APOIO AOS PROJETOS E ATIVIDADES SUPRAMENCIONADOS COM O APORTE DE RECURSOS DE EMENDAS PARLAMENTARES NA LEI ORÇAMENTÁRIA ANUAL (LOA) DE 2026.
A9: 13 | B9: DEFESA | C9: 15680003 | D9: INDIVIDUAL | E9: INCLUSÃO - APROPRIAÇÃO | F9: 1568 | G9: GILBERTO NASCIMENTO | H9: DEPUTADO FEDERAL | I9: SP | J9: PODE | K9: 52000 | L9: MINISTÉRIO DA DEFESA | M9: 52121 | N9: COMANDO DO EXÉRCITO | O9: 05.301.0032.2E74.3928 | P9: DEFESA NACIONAL | Q9: ATENÇÃO BÁSICA | R9: PROGRAMA DE GESTÃO E MANUTENÇÃO DO PODER EXECUTIVO | S9: ESTRUTURAÇÃO E MODERNIZAÇÃO DE UNIDADES DE SAÚDE DAS FORÇAS ARMADAS | T9: NO MUNICÍPIO DE SÃO PAULO - SP | U9: SP | V9: SÃO PAULO | W9: S | X9: 4 | Y9: 90 | Z9: 0 | AA9: 6 | AB9: 1000 | AC9: 500000 | AD9: BENEFICIÁRIO PARA LANÇAMENTO NO SIOP - CNPJ: 00.394.452/0001-03_x000D_ REALIZAR A BIÓPSIA DE PRÓSTATA POR VIA TRANSPERINEAL, UTILIZANDO ULTRASSONOGRAFIA COM SOFTWARE DE FUSÃO DE IMAGENS EM TEMPO REAL, O QUE PERMITE EXAMES MAIS RÁPIDOS E PRECISOS, ALÉM DE GERAR ECONOMIA COM A REDUÇÃO DE ENCAMINHAMENTOS._x000D_ A AQUISIÇÃO DO EQUIPAMENTO CELL SAVER MINIMIZARÁ A NECESSIDADE DE SANGUE DE DOADORES, REDUZINDO O RISCO DE COMPLICAÇÕES ASSOCIADAS ÀS TRANSFUSÕES ALOGÊNICAS. O USO DO PRÓPRIO SANGUE DO PACIENTE REDUZ O RISCO DE INCOMPATIBILIDADE SANGUÍNEA E DE TRANSMISSÃO DE DOENÇAS INFECCIOSAS._x000D_ _x000D_ HOSPITAL MILITAR DE ÁREA DE SÃO PAULO (HMASP), NO MUNICÍPIO DE SÃO PAULO - SP. | AE9: HMASP | AF9: Aparelho de ultrassom e Cell Saver
A10: 13 | B10: DEFESA | C10: 15680014 | D10: INDIVIDUAL | E10: ACRÉSCIMO - APROPRIAÇÃO | F10: 1568 | G10: GILBERTO NASCIMENTO | H10: DEPUTADO FEDERAL | I10: SP | J10: PODE | K10: 52000 | L10: MINISTÉRIO DA DEFESA | M10: 52931 | N10: FUNDO NAVAL | O10: 05.122.0032.2000.0001 | P10: DEFESA NACIONAL | Q10: ADMINISTRAÇÃO GERAL | R10: PROGRAMA DE GESTÃO E MANUTENÇÃO DO PODER EXECUTIVO | S10: ADMINISTRAÇÃO DA UNIDADE | T10: NACIONAL | U10: NA | V10: NACIONAL | W10: F | X10: 3 | Y10: 90 | Z10: 0 | AA10: 6 | AB10: 1000 | AC10: 300000 | AD10: COMANDO DO 8º DISTRITO NAVAL - COM8ºDN_x000D_ CNPJ: 00.394.502/0455-98_x000D_ _x000D_ "O COMANDO DO 8º DISTRITO NAVAL, NO ÂMBITO DE SUAS ATRIBUIÇÕES COMO REPRESENTANTE DA AUTORIDADE MARÍTIMA, COORDENA OS SERVIÇOS DE BUSCA, SALVAMENTO, FISCALIZAÇÃO E INSPEÇÃO NAVAL NOS ESTADOS DE SÃO PAULO E PARANÁ._x000D_ POR MEIO DE SEUS DOIS GRUPAMENTOS OPERATIVOS: O GRUPAMENTO DE PATRULHA NAVAL DO SUL-SUDESTE (COM SEUS 03 NAVIOS) E O 4º BATALHÃO DE OPERAÇÕES LITORÂNEAS DE FUZILEIROS NAVAIS, EM SANTOS-SP, (COM SEU EFETIVO DE 01 COMPANHIA) COMANDA OPERAÇÕES NAVAIS, CONJUNTAS E INTERAGÊNCIAS EM TODO O LITORAL PAULISTA, PARANAENSE, INTERIORES E FRONTEIRA OESTE._x000D_ NESSE SENTIDO, VISANDO MELHORAR E APRIMORAR A SUA CAPACIDADE OPERACIONAL PARA O CUMPRIMENTO DE SUA MISSÃO, O COMANDO DO 8º DISTRITO NAVAL NECESSITA DE VIATURAS PRONTAS E ADEQUADAS, E CAPAZES DE TRANSPORTAR SEUS MILITARES NA AMPLA ÁREA DE JURISDIÇÃO DOS DOIS ESTADOS DA FEDERAÇÃO E ESTAR APTO A PRESTAR OS DEVERES CONSTITUCIONAIS E SEUS SERVIÇOS À SOCIEDADE CIVIL._x000D_ A MANUTENÇÃO DESSES MEIOS SÃO DE VITAL IMPORTÂNCIA PARA QUE POSSAMOS ESTAR PRONTOS PARA O ATENDIMENTO DAS DEMANDAS DA SOCIEDADE, COM VISTAS A DESLOCAR PESSOAL E MEIOS, VIA RODOVIÁRIA, QUANDO NECESSÁRIO, PRESERVAR À SEGURANÇA DA NAVEGAÇÃO, SALVAGUARDA DA VIDA HUMANA NO MAR E PREVENIR A POLUIÇÃO HÍDRICA._x000D_ EM FACE DAS ATUAIS RESTRIÇÕES ORÇAMENTÁRIAS, COMPREENDEMOS QUE NOSSAS NECESSIDADES ESTÃO ACIMA DAS POSSIBILIDADES DE INVESTIMENTO E, POR ESSE MOTIVO, SUBMETEMOS À APRECIAÇÃO DE VOSSA EXCELÊNCIA, COMO PARTÍCIPE DA GESTÃO PÚBLICA EM FAVOR DO NOSSO ESTADO, A PRESENTE PROPOSTA DE EMENDA PARLAMENTAR, TENDO COMO BENEFICIÁRIO O COM8ºDN."
A11: 13 | B11: DEFESA | C11: 15810007 | D11: INDIVIDUAL | E11: INCLUSÃO - APROPRIAÇÃO | F11: 1581 | G11: JEFFERSON CAMPOS | H11: DEPUTADO FEDERAL | I11: SP | J11: PL | K11: 52000 | L11: MINISTÉRIO DA DEFESA | M11: 52121 | N11: COMANDO DO EXÉRCITO | O11: 05.153.6112.21A0. | P11: DEFESA NACIONAL | Q11: DEFESA TERRESTRE | R11: DEFESA NACIONAL | S11: APRESTAMENTO DAS FORÇAS - MANUTENÇÃO DA PRONTIDÃO E DA CAPACIDADE OPERATIVA | T11: COLEGIO MILITAR DE SÃO PAULO (CMSP) MUNICIPIO DE SÃO PAULO, INSTRUMENTOS MUSICAIS E EQUIPAMENTTOS DE APOIO PARA BANDA DE MUSICA - NACIONAL | U11: NA | V11: NACIONAL | W11: F | X11: 3 | Y11: 90 | Z11: 0 | AA11: 6 | AB11: 1000 | AC11: 200000 | AD11: BENEFICIARIO PARA LANÇAMENTO NO SIOP CNPJ. 00.394.452/0001-03, ADIQUIRIR NOVOS INSTRUMENTOS E EQUIPAMENTOS, MELHORANDO AS CONDIÇÕES PARA OS ENSAIOS E APRESENTAÇÃO DA BANDA DE MUSICA DA UNIDADE, QUE APOIA DIVERSOS EVENTOS CULTURAIS NO MUNICIPIO DE SÃO PAULO - SP. | AE11: CPOR/SP | AF11: Instrumentos musicais
A12: 13 | B12: DEFESA | C12: 15810007 | D12: INDIVIDUAL | E12: INCLUSÃO - APROPRIAÇÃO | F12: 1581 | G12: JEFFERSON CAMPOS | H12: DEPUTADO FEDERAL | I12: SP | J12: PL | K12: 52000 | L12: MINISTÉRIO DA DEFESA | M12: 52121 | N12: COMANDO DO EXÉRCITO | O12: 05.153.6112.21A0. | P12: DEFESA NACIONAL | Q12: DEFESA TERRESTRE | R12: DEFESA NACIONAL | S12: APRESTAMENTO DAS FORÇAS - MANUTENÇÃO DA PRONTIDÃO E DA CAPACIDADE OPERATIVA | T12: COLEGIO MILITAR DE SÃO PAULO (CMSP) MUNICIPIO DE SÃO PAULO, INSTRUMENTOS MUSICAIS E EQUIPAMENTTOS DE APOIO PARA BANDA DE MUSICA - NACIONAL | U12: NA | V12: NACIONAL | W12: F | X12: 4 | Y12: 90 | Z12: 0 | AA12: 6 | AB12: 1000 | AC12: 200000 | AD12: BENEFICIARIO PARA LANÇAMENTO NO SIOP CNPJ. 00.394.452/0001-03, ADIQUIRIR NOVOS INSTRUMENTOS E EQUIPAMENTOS, MELHORANDO AS CONDIÇÕES PARA OS ENSAIOS E APRESENTAÇÃO DA BANDA DE MUSICA DA UNIDADE, QUE APOIA DIVERSOS EVENTOS CULTURAIS NO MUNICIPIO DE SÃO PAULO - SP. | AE12: CPOR/SP | AF12: Instrumentos musicais
A13: 13 | B13: DEFESA | C13: 18670002 | D13: INDIVIDUAL | E13: INCLUSÃO - APROPRIAÇÃO | F13: 1867 | G13: LUIZ CARLOS HAULY | H13: DEPUTADO FEDERAL | I13: PR | J13: PODE | K13: 52000 | L13: MINISTÉRIO DA DEFESA | M13: 52111 | N13: COMANDO DA AERONÁUTICA | O13: 05.301.0032.2E74.0001 | P13: DEFESA NACIONAL | Q13: ATENÇÃO BÁSICA | R13: PROGRAMA DE GESTÃO E MANUTENÇÃO DO PODER EXECUTIVO | S13: ESTRUTURAÇÃO E MODERNIZAÇÃO DE UNIDADES DE SAÚDE DAS FORÇAS ARMADAS | T13: NACIONAL | U13: NA | V13: NACIONAL | W13: S | X13: 4 | Y13: 90 | Z13: 0 | AA13: 6 | AB13: 1000 | AC13: 250000 | AD13: CNPJ PARA LANÇAMENTO NO SIOP: 00.394.429/0001-00 - COMANDO DA AERONÁUTICA_x000D_ OM BENEFICIADA: GRUPO DE SAÚDE DE CURITIBA_x000D_ OBJETO RESUMIDO: AQUISIÇÃO DE APARELHO DE VIDEOENDOSCÓPIO._x000D_ JUSTIFICATIVA:_x000D_ A FORÇA AÉREA BRASILEIRA (FAB), COMO INSTITUIÇÃO DE ESTADO, ATUA, ININTERRUPTAMENTE, NA DEFESA DA PÁTRIA, NA MANUTENÇÃO DA SOBERANIA DO NOSSO ESPAÇO AÉREO, NA PROTEÇÃO DE NOSSAS FRONTEIRAS E NA INTEGRAÇÃO DO TERRITÓRIO NACIONAL._x000D_ ADEMAIS, SUBSIDIARIAMENTE, A FAB CUMPRE MISSÕES HUMANITÁRIAS E DE REPATRIAÇÃO DE NACIONAIS, DE TRANSPORTE DE ÓRGÃOS E TECIDOS, BEM COMO CONTRIBUI COM O DESENVOLVIMENTO TECNOLÓGICO, GERANDO EMPREGOS E RIQUEZAS AO PAÍS._x000D_ PELO EXPOSTO, PARA CONTRIBUIR COM A FAB NO CUMPRIMENTO DE SUA MISSÃO CONSTITUCIONAL EM BENEFÍCIO DA SOCIEDADE BRASILEIRA, É NECESSÁRIO O APOIO AOS PROJETOS E ATIVIDADES SUPRAMENCIONADOS COM O APORTE DE RECURSOS DE EMENDAS PARLAMENTARES NA LEI ORÇAMENTÁRIA ANUAL (LOA) DE 2026.
A14: 13 | B14: DEFESA | C14: 19600024 | D14: INDIVIDUAL | E14: INCLUSÃO - APROPRIAÇÃO | F14: 1960 | G14: RUBENS OTONI | H14: DEPUTADO FEDERAL | I14: GO | J14: PT | K14: 52000 | L14: MINISTÉRIO DA DEFESA | M14: 52111 | N14: COMANDO DA AERONÁUTICA | O14: 05.122.0032.2000.0052 | P14: DEFESA NACIONAL | Q14: ADMINISTRAÇÃO GERAL | R14: PROGRAMA DE GESTÃO E MANUTENÇÃO DO PODER EXECUTIVO | S14: ADMINISTRAÇÃO DA UNIDADE | T14: NO ESTADO DE GOIÁS | U14: GO | V14: GOIÁS | W14: F | X14: 3 | Y14: 90 | Z14: 0 | AA14: 6 | AB14: 1000 | AC14: 200000 | AD14: A FORÇA AÉREA BRASILEIRA (FAB), COMO INSTITUIÇÃO DE ESTADO, ATUA, ININTERRUPTAMENTE, NA DEFESA DA PÁTRIA, NA MANUTENÇÃO DA SOBERANIA DO NOSSO ESPAÇO AÉREO, NA PROTEÇÃO DE NOSSAS FRONTEIRAS E NA INTEGRAÇÃO DO TERRITÓRIO NACIONAL._x000D_ ADEMAIS, SUBSIDIARIAMENTE, A FAB CUMPRE MISSÕES HUMANITÁRIAS E DE REPATRIAÇÃO DE NACIONAIS, DE TRANSPORTE DE ÓRGÃOS E TECIDOS, BEM COMO CONTRIBUI COM O DESENVOLVIMENTO TECNOLÓGICO, GERANDO EMPREGOS E RIQUEZAS AO PAÍS._x000D_ PELO EXPOSTO, PARA CONTRIBUIR COM A FAB NO CUMPRIMENTO DE SUA MISSÃO CONSTITUCIONAL EM BENEFÍCIO DA SOCIEDADE BRASILEIRA, É NECESSÁRIO O APOIO AOS PROJETOS E ATIVIDADES SUPRAMENCIONADOS COM O APORTE DE RECURSOS DE EMENDAS PARLAMENTARES NA LEI ORÇAMENTÁRIA ANUAL (LOA) DE 2026."
A15: 13 | B15: DEFESA | C15: 20290015 | D15: INDIVIDUAL | E15: ACRÉSCIMO - APROPRIAÇÃO | F15: 2029 | G15: MAGNO MALTA | H15: SENADOR | I15: ES | J15: PL | K15: 52000 | L15: MINISTÉRIO DA DEFESA | M15: 52131 | N15: COMANDO DA MARINHA | O15: 05.152.6112.219D.0001 | P15: DEFESA NACIONAL | Q15: DEFESA NAVAL | R15: DEFESA NACIONAL | S15: ADEQUAÇÃO DE ATIVOS DE INFRAESTRUTURA DAS ORGANIZAÇÕES MILITARES | T15: NACIONAL | U15: NA | V15: NACIONAL | W15: F | X15: 3 | Y15: 90 | Z15: 0 | AA15: 6 | AB15: 1000 | AC15: 400000 | AD15: ESCOLA DE APRENDIZES-MARINHEIROS DO ESPÍRITO SANTO (EAMES)_x000D_ CNPJ: 00.394.502/0188-68_x000D_ _x000D_ ESTA PROPOSTA POR OBJETIVO A CONSTRUÇÃO DA GARAGEM DE BARCOS DA ESCOLA DE APRENDIZES-MARINHEIROS DO ESPÍRITO SANTO (EAMES). A ESTRUTURA DESEJADA VISA ATENDER A NECESSIDADE DA GUARDA/CONSERVAÇÃO DAS EMBARCAÇÕES MIÚDAS, MATERIAIS E EQUIPAMENTOS QUE SÃO IMPRESCINDÍVEIS NO APOIO ÀS ATIVIDADES NÁUTICAS DE VELA E REMO, MODALIDADES ESTAS, INTEGRANTES DA FORMAÇÃO DOS MARINHEIROS DA MARINHA DO BRASIL. OUTROSSIM, AS ATIVIDADES NÁUTICAS DE VELA SÃO OFERECIDAS À 400 CRIANÇAS ATENDIDAS PELO PROGRAMA FORÇAS NO ESPORTE (PROFESP), ORIUNDAS DE 12 ESCOLAS DA REDE PÚBLICA DE ENSINO DO MUNICÍPIO DE VILA VELHA-ES, VISANDO À INCLUSÃO SOCIAL POR MEIO DA PRÁTICA ESPORTIVA ORIENTADA. OUTRA POSSIBILIDADE DE EMPREGO DO ESPAÇO SERIA EM PROVEITO DAS ATIVIDADES PRATICADAS PELOS ESCOTEIROS DO MAR, PARCEIROS DA MARINHA DO BRASIL QUE, POR MEIO DE SUA VERTENTE ESPECÍFICA DO ESCOTISMO, TÊM O OBJETIVO DE DESENVOLVER NOS JOVENS O GOSTO PELO MAR E HABILIDADES MARINHEIRAS, CONTRIBUINDO NO FOMENTO DA MENTALIDADE MARÍTIMA DA SOCIEDADE CAPIXABA.
A16: 13 | B16: DEFESA | C16: 20830009 | D16: INDIVIDUAL | E16: INCLUSÃO - APROPRIAÇÃO | F16: 2083 | G16: ANDRÉ FIGUEIREDO | H16: DEPUTADO FEDERAL | I16: CE | J16: PDT | K16: 52000 | L16: MINISTÉRIO DA DEFESA | M16: 52931 | N16: FUNDO NAVAL | O16: 05.125.6112.21BY.0023 | P16: DEFESA NACIONAL | Q16: NORMATIZAÇÃO E FISCALIZAÇÃO | R16: DEFESA NACIONAL | S16: FISCALIZAÇÃO DA NAVEGAÇÃO AQUAVIÁRIA | T16: NO ESTADO DO CEARÁ | U16: CE | V16: CEARÁ | W16: F | X16: 4 | Y16: 90 | Z16: 0 | AA16: 6 | AB16: 1000 | AC16: 100000 | AD16: AUXILIAR A CAPITANIA DOS PORTOS NO CEARA A DESENVOLVER SUAS ATIVIDADES DE PROTEÇÃO E FISCALIZAÇÃO
A17: 13 | B17: DEFESA | C17: 22100001 | D17: INDIVIDUAL | E17: ACRÉSCIMO - APROPRIAÇÃO | F17: 2210 | G17: ESPERIDIÃO AMIN | H17: SENADOR | I17: SC | J17: PP | K17: 52000 | L17: MINISTÉRIO DA DEFESA | M17: 52131 | N17: COMANDO DA MARINHA | O17: 05.152.6112.219D.0001 | P17: DEFESA NACIONAL | Q17: DEFESA NAVAL | R17: DEFESA NACIONAL | S17: ADEQUAÇÃO DE ATIVOS DE INFRAESTRUTURA DAS ORGANIZAÇÕES MILITARES | T17: NACIONAL | U17: NA | V17: NACIONAL | W17: F | X17: 3 | Y17: 90 | Z17: 0 | AA17: 6 | AB17: 1000 | AC17: 900000 | AD17: CAPITANIA DOS PORTOS DE SANTA CATARINA - CPSC_x000D_ CNPJ: 00.394.502/0048-08_x000D_ _x000D_ A PRESENTE PROPOSTA TEM COMO OBJETIVOS:_x000D_ A) DAR CONTINUIDADE À RECUPERAÇÃO DO FORTE SANTA BÁRBARA, DA CASA DE APOIO E DO AUDITÓRIO AMAZÔNIA AZUL, ALÉM DE ADAPTAR O MUSEU DE ARQUEOLOGIA SUBAQUÁTICA. O FORTE SANTA BÁRBARA ABRIGA O CCMSC, SENDO ESTE UM IMPORTANTE ATRATIVO CULTURAL, TURÍSTICO E EDUCACIONAL, QUE BUSCA DISSEMINAR A MENTALIDADE MARÍTIMA E OFERECENDO UMA OPÇÃO CULTURAL E DE LAZER PARA A POPULAÇÃO CATARINENSE. DESDE SUA ABERTURA EM 2016, O CENTRO RECEBEU MAIS DE 28.000 VISITANTES E DESEMPENHA UM PAPEL SIGNIFICATIVO NA DIVULGAÇÃO DA HISTÓRIA, DA MENTALIDADE MARÍTIMA E DAS TRADIÇÕES MARINHEIRAS. NO ENTANTO, AS EDIFICAÇÕES DO CENTRO ESTÃO BASTANTE DEGRADADAS E HÁ UMA FALTA DE ACESSIBILIDADE ADEQUADA PARA PESSOAS COM NECESSIDADES ESPECIAIS. A REVITALIZAÇÃO PERMITIRÁ A PRESERVAÇÃO DO PATRIMÔNIO HISTÓRICO E CULTURAL, GARANTIRÁ A INTEGRIDADE E A SEGURANÇA DOS VISITANTES, ESTIMULARÁ O TURISMO E FOMENTARÁ A ECONOMIA LOCAL._x000D_ B) RECUPERAR E REVITALIZAR AS INSTALAÇÕES DO CASARÃO DA ILHA DO ARVOREDO E SUAS ADJACÊNCIAS, ALÉM DA MANUTENÇÃO DOS SINAIS NÁUTICOS. CONSIDERANDO A IMPORTÂNCIA DOS AUXÍLIOS À NAVEGAÇÃO PARA O DESENVOLVIMENTO DAS ATIVIDADES MARÍTIMAS, É NECESSÁRIO GARANTIR O PLENO FUNCIONAMENTO DOS DIVERSOS FARÓIS E FAROLETES AO LONGO DA COSTA CATARINENSE, QUE CONFEREM SEGURANÇA À NAVEGAÇÃO PARA A COMUNIDADE MARÍTIMA. O INVESTIMENTO VISA ASSEGURAR A CONTINUIDADE E A EFICÁCIA DESSES DISPOSITIVOS DE SEGURANÇA._x000D_ C) RECUPERAÇÃO DAS INSTALAÇÕES DO FAROL DA ILHA DA PAZ, ALIADA À IMPLANTAÇÃO DE UM SISTEMA FOTOVOLTAICO, VISANDO AMPLIAR A AUTONOMIA ENERGÉTICA LOCAL, REDUZIR CUSTOS OPERACIONAIS E ASSEGURAR A CONTINUIDADE DAS ATIVIDADES DESEMPENHADAS.
A18: 13 | B18: DEFESA | C18: 22100001 | D18: INDIVIDUAL | E18: ACRÉSCIMO - APROPRIAÇÃO | F18: 2210 | G18: ESPERIDIÃO AMIN | H18: SENADOR | I18: SC | J18: PP | K18: 52000 | L18: MINISTÉRIO DA DEFESA | M18: 52131 | N18: COMANDO DA MARINHA | O18: 05.152.6112.219D.0001 | P18: DEFESA NACIONAL | Q18: DEFESA NAVAL | R18: DEFESA NACIONAL | S18: ADEQUAÇÃO DE ATIVOS DE INFRAESTRUTURA DAS ORGANIZAÇÕES MILITARES | T18: NACIONAL | U18: NA | V18: NACIONAL | W18: F | X18: 4 | Y18: 90 | Z18: 0 | AA18: 6 | AB18: 1000 | AC18: 600000 | AD18: CAPITANIA DOS PORTOS DE SANTA CATARINA - CPSC_x000D_ CNPJ: 00.394.502/0048-08_x000D_ _x000D_ A PRESENTE PROPOSTA TEM COMO OBJETIVOS:_x000D_ A) DAR CONTINUIDADE À RECUPERAÇÃO DO FORTE SANTA BÁRBARA, DA CASA DE APOIO E DO AUDITÓRIO AMAZÔNIA AZUL, ALÉM DE ADAPTAR O MUSEU DE ARQUEOLOGIA SUBAQUÁTICA. O FORTE SANTA BÁRBARA ABRIGA O CCMSC, SENDO ESTE UM IMPORTANTE ATRATIVO CULTURAL, TURÍSTICO E EDUCACIONAL, QUE BUSCA DISSEMINAR A MENTALIDADE MARÍTIMA E OFERECENDO UMA OPÇÃO CULTURAL E DE LAZER PARA A POPULAÇÃO CATARINENSE. DESDE SUA ABERTURA EM 2016, O CENTRO RECEBEU MAIS DE 28.000 VISITANTES E DESEMPENHA UM PAPEL SIGNIFICATIVO NA DIVULGAÇÃO DA HISTÓRIA, DA MENTALIDADE MARÍTIMA E DAS TRADIÇÕES MARINHEIRAS. NO ENTANTO, AS EDIFICAÇÕES DO CENTRO ESTÃO BASTANTE DEGRADADAS E HÁ UMA FALTA DE ACESSIBILIDADE ADEQUADA PARA PESSOAS COM NECESSIDADES ESPECIAIS. A REVITALIZAÇÃO PERMITIRÁ A PRESERVAÇÃO DO PATRIMÔNIO HISTÓRICO E CULTURAL, GARANTIRÁ A INTEGRIDADE E A SEGURANÇA DOS VISITANTES, ESTIMULARÁ O TURISMO E FOMENTARÁ A ECONOMIA LOCAL._x000D_ B) RECUPERAR E REVITALIZAR AS INSTALAÇÕES DO CASARÃO DA ILHA DO ARVOREDO E SUAS ADJACÊNCIAS, ALÉM DA MANUTENÇÃO DOS SINAIS NÁUTICOS. CONSIDERANDO A IMPORTÂNCIA DOS AUXÍLIOS À NAVEGAÇÃO PARA O DESENVOLVIMENTO DAS ATIVIDADES MARÍTIMAS, É NECESSÁRIO GARANTIR O PLENO FUNCIONAMENTO DOS DIVERSOS FARÓIS E FAROLETES AO LONGO DA COSTA CATARINENSE, QUE CONFEREM SEGURANÇA À NAVEGAÇÃO PARA A COMUNIDADE MARÍTIMA. O INVESTIMENTO VISA ASSEGURAR A CONTINUIDADE E A EFICÁCIA DESSES DISPOSITIVOS DE SEGURANÇA._x000D_ C) RECUPERAÇÃO DAS INSTALAÇÕES DO FAROL DA ILHA DA PAZ, ALIADA À IMPLANTAÇÃO DE UM SISTEMA FOTOVOLTAICO, VISANDO AMPLIAR A AUTONOMIA ENERGÉTICA LOCAL, REDUZIR CUSTOS OPERACIONAIS E ASSEGURAR A CONTINUIDADE DAS ATIVIDADES DESEMPENHADAS.
A19: 13 | B19: DEFESA | C19: 22100002 | D19: INDIVIDUAL | E19: ACRÉSCIMO - APROPRIAÇÃO | F19: 2210 | G19: ESPERIDIÃO AMIN | H19: SENADOR | I19: SC | J19: PP | K19: 52000 | L19: MINISTÉRIO DA DEFESA | M19: 52121 | N19: COMANDO DO EXÉRCITO | O19: 05.122.0032.2000.0001 | P19: DEFESA NACIONAL | Q19: ADMINISTRAÇÃO GERAL | R19: PROGRAMA DE GESTÃO E MANUTENÇÃO DO PODER EXECUTIVO | S19: ADMINISTRAÇÃO DA UNIDADE | T19: NACIONAL | U19: NA | V19: NACIONAL | W19: F | X19: 4 | Y19: 90 | Z19: 0 | AA19: 6 | AB19: 1000 | AC19: 850000 | AD19: BENEFICIÁRIO PARA LANÇAMENTO NO SIOP - CNPJ: 00.394.452/0001-03_x000D_ REDUZIR DESPESAS DE CUSTEIO COM ENERGIA ELÉTRICA, AUMENTAR A SEGURANÇA ENERGÉTICA DA UNIDADE E CONTRIBUIR PARA A PRESERVAÇÃO DO MEIO AMBIENTE E DESENVOLVIMENTO SUSTENTÁVEL._x000D_ _x000D_ 63º BATALHÃO DE INFANTARIA (63º BI), NO MUNICÍPIO DE FLORIANÓPOLIS - SC | AE19: 63º BI | AF19: Usina fotovoltaica
A20: 13 | B20: DEFESA | C20: 22100020 | D20: INDIVIDUAL | E20: INCLUSÃO - APROPRIAÇÃO | F20: 2210 | G20: ESPERIDIÃO AMIN | H20: SENADOR | I20: SC | J20: PP | K20: 52000 | L20: MINISTÉRIO DA DEFESA | M20: 52111 | N20: COMANDO DA AERONÁUTICA | O20: 05.301.0032.2E74.0042 | P20: DEFESA NACIONAL | Q20: ATENÇÃO BÁSICA | R20: PROGRAMA DE GESTÃO E MANUTENÇÃO DO PODER EXECUTIVO | S20: ESTRUTURAÇÃO E MODERNIZAÇÃO DE UNIDADES DE SAÚDE DAS FORÇAS ARMADAS | T20: NO ESTADO DE SANTA CATARINA | U20: SC | V20: SANTA CATARINA | W20: S | X20: 4 | Y20: 90 | Z20: 0 | AA20: 6 | AB20: 1000 | AC20: 500000 | AD20: CNPJ PARA LANÇAMENTO NO SIOP: 00.394.429/0001-00 - COMANDO DA AERONÁUTICA_x000D_ OM BENEFICIADA: GRUPO DE SAÚDE DE FLORIANÓPOLIS_x000D_ OBJETO RESUMIDO: AQUISIÇÃO DE EQUIPAMENTOS MÉDICOS E ODONTOLÓGICOS._x000D_ JUSTIFICATIVA:_x000D_ A FORÇA AÉREA BRASILEIRA (FAB), COMO INSTITUIÇÃO DE ESTADO, ATUA, ININTERRUPTAMENTE, NA DEFESA DA PÁTRIA, NA MANUTENÇÃO DA SOBERANIA DO NOSSO ESPAÇO AÉREO, NA PROTEÇÃO DE NOSSAS FRONTEIRAS E NA INTEGRAÇÃO DO TERRITÓRIO NACIONAL._x000D_ ADEMAIS, SUBSIDIARIAMENTE, A FAB CUMPRE MISSÕES HUMANITÁRIAS E DE REPATRIAÇÃO DE NACIONAIS, DE TRANSPORTE DE ÓRGÃOS E TECIDOS, BEM COMO CONTRIBUI COM O DESENVOLVIMENTO TECNOLÓGICO, GERANDO EMPREGOS E RIQUEZAS AO PAÍS._x000D_ PELO EXPOSTO, PARA CONTRIBUIR COM A FAB NO CUMPRIMENTO DE SUA MISSÃO CONSTITUCIONAL EM BENEFÍCIO DA SOCIEDADE BRASILEIRA, É NECESSÁRIO O APOIO AOS PROJETOS E ATIVIDADES SUPRAMENCIONADOS COM O APORTE DE RECURSOS DE EMENDAS PARLAMENTARES NA LEI ORÇAMENTÁRIA ANUAL (LOA) DE 2026.
A21: 13 | B21: DEFESA | C21: 22630007 | D21: INDIVIDUAL | E21: ACRÉSCIMO - APROPRIAÇÃO | F21: 2263 | G21: JADER BARBALHO | H21: SENADOR | I21: PA | J21: MDB | K21: 52000 | L21: MINISTÉRIO DA DEFESA | M21: 52121 | N21: COMANDO DO EXÉRCITO | O21: 05.153.6112.21A0.0001 | P21: DEFESA NACIONAL | Q21: DEFESA TERRESTRE | R21: DEFESA NACIONAL | S21: APRESTAMENTO DAS FORÇAS - MANUTENÇÃO DA PRONTIDÃO E DA CAPACIDADE OPERATIVA | T21: NACIONAL | U21: NA | V21: NACIONAL | W21: F | X21: 4 | Y21: 90 | Z21: 0 | AA21: 6 | AB21: 1000 | AC21: 200000 | AD21: BENEFICIÁRIO PARA LANÇAMENTO NO SIOP - CNPJ: 00.394.452/0001-03_x000D_ INSTRUMENTOS MUSICAIS PARA A BANDA DE MÚSICA DOS ALUNOS DO COLÉGIO MILITAR DE BELÉM (CMBEL), NO MUNICÍPIO DE BELÉM - PA. ADQUIRIR NOVOS INSTRUMENTOS, MELHORANDO AS CONDIÇÕES PARA OS ENSAIOS E APRESENTAÇÕES DA BANDA DE MÚSICA DOS ALUNOS, QUE APOIA DIVERSOS EVENTOS CULTURAIS NO MUNICÍPIO. | AE21: 2º BIS | AF21: Ambulância tipo “B” – Suporte básico
A22: 13 | B22: DEFESA | C22: 22630008 | D22: INDIVIDUAL | E22: ACRÉSCIMO - APROPRIAÇÃO | F22: 2263 | G22: JADER BARBALHO | H22: SENADOR | I22: PA | J22: MDB | K22: 52000 | L22: MINISTÉRIO DA DEFESA | M22: 52931 | N22: FUNDO NAVAL | O22: 05.152.6112.21A0.0001 | P22: DEFESA NACIONAL | Q22: DEFESA NAVAL | R22: DEFESA NACIONAL | S22: APRESTAMENTO DAS FORÇAS - MANUTENÇÃO DA PRONTIDÃO E DA CAPACIDADE OPERATIVA | T22: NACIONAL | U22: NA | V22: NACIONAL | W22: F | X22: 3 | Y22: 90 | Z22: 0 | AA22: 6 | AB22: 1000 | AC22: 500000 | AD22: GRUPAMENTO DE PATRULHA NAVAL DO NORTE_x000D_ CNPJ: 00.394.502/0152-57_x000D_ _x000D_ CUSTEIO DA MANUTENÇÃO E A PREPARAÇÃO DOS NAVIOS E EMBARCAÇÕES SUBORDINADAS, QUE REALIZAM AÇÕES CÍVICO-SOCIAIS (ACISO) E ASSISTÊNCIAS HOSPITALARES (ASSHOP), E QUE APOIAM, QUANDO NECESSÁRIO, NOS ATENDIMENTOS REALIZADOS PELO NÁVIO-AUXILIAR “PARÁ” E PELO NAVIO DE ASSISTÊNCIA HOSPITALAR “SARGENTO LIMA”, PROPICIANDO O ACESSO ÀS ÁREAS REMOTAS, QUANDO DO SEU EMPREGO EM OPERAÇÕES DE APOIO AO ESTADO DO PARÁ.
A23: 13 | B23: DEFESA | C23: 22630009 | D23: INDIVIDUAL | E23: INCLUSÃO - APROPRIAÇÃO | F23: 2263 | G23: JADER BARBALHO | H23: SENADOR | I23: PA | J23: MDB | K23: 52000 | L23: MINISTÉRIO DA DEFESA | M23: 52911 | N23: FUNDO AERONÁUTICO | O23: 05.368.6112.21GP.0015 | P23: DEFESA NACIONAL | Q23: EDUCAÇÃO BÁSICA | R23: DEFESA NACIONAL | S23: FUNCIONAMENTO DOS ESTABELECIMENTOS DE EDUCAÇÃO BÁSICA MILITARES DO MINISTÉRIO DA DEFESA | T23: NO ESTADO DO PARÁ | U23: PA | V23: PARÁ | W23: F | X23: 4 | Y23: 90 | Z23: 0 | AA23: 6 | AB23: 1000 | AC23: 500000 | AD23: CNPJ PARA LANÇAMENTO NO SIOP: 00.394.429/0001-00 - COMANDO DA AERONÁUTICA_x000D_ OM BENEFICIADA: COLÉGIO TENENTE RÊGO BARROS_x000D_ OBJETO RESUMIDO: AQUISIÇÃO DE MOBILIÁRIO E READEQUAÇÃO DAS SALAS DOS PROFESSORES._x000D_ JUSTIFICATIVA:_x000D_ A FORÇA AÉREA BRASILEIRA (FAB), COMO INSTITUIÇÃO DE ESTADO, ATUA, ININTERRUPTAMENTE, NA DEFESA DA PÁTRIA, NA MANUTENÇÃO DA SOBERANIA DO NOSSO ESPAÇO AÉREO, NA PROTEÇÃO DE NOSSAS FRONTEIRAS E NA INTEGRAÇÃO DO TERRITÓRIO NACIONAL._x000D_ ADEMAIS, SUBSIDIARIAMENTE, A FAB CUMPRE MISSÕES HUMANITÁRIAS E DE REPATRIAÇÃO DE NACIONAIS, DE TRANSPORTE DE ÓRGÃOS E TECIDOS, BEM COMO CONTRIBUI COM O DESENVOLVIMENTO TECNOLÓGICO, GERANDO EMPREGOS E RIQUEZAS AO PAÍS._x000D_ PELO EXPOSTO, PARA CONTRIBUIR COM A FAB NO CUMPRIMENTO DE SUA MISSÃO CONSTITUCIONAL EM BENEFÍCIO DA SOCIEDADE BRASILEIRA, É NECESSÁRIO O APOIO AOS PROJETOS E ATIVIDADES SUPRAMENCIONADOS COM O APORTE DE RECURSOS DE EMENDAS PARLAMENTARES NA LEI ORÇAMENTÁRIA ANUAL (LOA) DE 2026.
A24: 13 | B24: DEFESA | C24: 23760004 | D24: INDIVIDUAL | E24: ACRÉSCIMO - APROPRIAÇÃO | F24: 2376 | G24: JAYME CAMPOS | H24: SENADOR | I24: MT | J24: UNIÃO | K24: 52000 | L24: MINISTÉRIO DA DEFESA | M24: 52121 | N24: COMANDO DO EXÉRCITO | O24: 05.153.6112.21A0.0001 | P24: DEFESA NACIONAL | Q24: DEFESA TERRESTRE | R24: DEFESA NACIONAL | S24: APRESTAMENTO DAS FORÇAS - MANUTENÇÃO DA PRONTIDÃO E DA CAPACIDADE OPERATIVA | T24: NACIONAL | U24: NA | V24: NACIONAL | W24: F | X24: 4 | Y24: 90 | Z24: 0 | AA24: 6 | AB24: 1000 | AC24: 1000000 | AD24: A PRESENTE EMENDA TEM POR OBJETIVO DOTAR O BATALHÃO COM EQUIPAMENTOS NECESSÁRIOS PARA AS AÇÕES DE PRONTO ATENDIMENTO A CALAMIDADE PÚBLICA, COMBATE E PREVENÇÃO A INCÊNDIOS FLORESTAIS NO ESTADO DE MATO GROSSO. _x000D_ NA UNIDADE DO BATALHÃO DE CUIABÁ. CNPJ: 00.394.452/0001-03. | AE24: 9º BEC | AF24: Equipar OM de Engenharia para pronto atendimento a calamidades públicas
A25: 13 | B25: DEFESA | C25: 23760005 | D25: INDIVIDUAL | E25: ACRÉSCIMO - APROPRIAÇÃO | F25: 2376 | G25: JAYME CAMPOS | H25: SENADOR | I25: MT | J25: UNIÃO | K25: 52000 | L25: MINISTÉRIO DA DEFESA | M25: 52931 | N25: FUNDO NAVAL | O25: 05.152.6112.21A0.0001 | P25: DEFESA NACIONAL | Q25: DEFESA NAVAL | R25: DEFESA NACIONAL | S25: APRESTAMENTO DAS FORÇAS - MANUTENÇÃO DA PRONTIDÃO E DA CAPACIDADE OPERATIVA | T25: NACIONAL | U25: NA | V25: NACIONAL | W25: F | X25: 4 | Y25: 90 | Z25: 0 | AA25: 6 | AB25: 1000 | AC25: 500000 | AD25: A PRESENTE EMENDA TEM POR OBJETIVO REALIZAR INVESTIMENTOS NAS INSTALAÇÕES DA CAPITANIA FLUVIAL DE MATO GROSSO._x000D_ CAPITANIA FLUVIAL DE MATO GROSSO_x000D_ CNPJ: 00.394.502/0371-45
A26: 13 | B26: DEFESA | C26: 23920005 | D26: INDIVIDUAL | E26: INCLUSÃO - APROPRIAÇÃO | F26: 2392 | G26: FERNANDO COELHO FILHO | H26: DEPUTADO FEDERAL | I26: PE | J26: UNIÃO | K26: 52000 | L26: MINISTÉRIO DA DEFESA | M26: 52121 | N26: COMANDO DO EXÉRCITO | O26: 05.301.0032.2E74.1689 | P26: DEFESA NACIONAL | Q26: ATENÇÃO BÁSICA | R26: PROGRAMA DE GESTÃO E MANUTENÇÃO DO PODER EXECUTIVO | S26: ESTRUTURAÇÃO E MODERNIZAÇÃO DE UNIDADES DE SAÚDE DAS FORÇAS ARMADAS | T26: NO MUNICÍPIO DE PETROLINA - PE | U26: PE | V26: PETROLINA | W26: S | X26: 4 | Y26: 90 | Z26: 0 | AA26: 6 | AB26: 1000 | AC26: 450000 | AD26: A PRESENTE EMENDA TEM COMO OBJETIVO FORTALECER A ESTRUTURA DE SAÚDE DO 72º BATALHÃO DE INFANTARIA DE CAATINGA (72º BI CAAT), LOCALIZADO NO MUNICÍPIO DE PETROLINA/PE, MEDIANTE A AQUISIÇÃO DE AMBULÂNCIA DESTINADA AO ATENDIMENTO DE MILITARES, ALUNOS DA UNIDADE E SEUS DEPENDENTES. O EQUIPAMENTO É ESSENCIAL PARA GARANTIR SUPORTE ADEQUADO EM SITUAÇÕES DE URGÊNCIA E NO TRANSPORTE SEGURO DE PACIENTES EM ESTADO GRAVE. | AE26: 72º BI Caat | AF26: Ambulância tipo “B” – Suporte básico
A27: 13 | B27: DEFESA | C27: 23920007 | D27: INDIVIDUAL | E27: INCLUSÃO - APROPRIAÇÃO | F27: 2392 | G27: FERNANDO COELHO FILHO | H27: DEPUTADO FEDERAL | I27: PE | J27: UNIÃO | K27: 52000 | L27: MINISTÉRIO DA DEFESA | M27: 52931 | N27: FUNDO NAVAL | O27: 05.122.0032.2000.0026 | P27: DEFESA NACIONAL | Q27: ADMINISTRAÇÃO GERAL | R27: PROGRAMA DE GESTÃO E MANUTENÇÃO DO PODER EXECUTIVO | S27: ADMINISTRAÇÃO DA UNIDADE | T27: NO ESTADO DE PERNAMBUCO | U27: PE | V27: PERNAMBUCO | W27: F | X27: 4 | Y27: 99 | Z27: 0 | AA27: 6 | AB27: 1000 | AC27: 250000 | AD27: A PRESENTE EMENDA TEM COMO FINALIDADE VIABILIZAR A AMPLIAÇÃO DO SISTEMA FOTOVOLTAICO DA ESCOLA DE APRENDIZES-MARINHEIROS DE PERNAMBUCO (EAMPE), GARANTINDO MAIOR EFICIÊNCIA ENERGÉTICA, REDUÇÃO DE CUSTOS OPERACIONAIS E MAIOR AUTONOMIA NO CONSUMO DE ENERGIA. A MEDIDA É ESTRATÉGICA PARA FORTALECER AS ATIVIDADES DA INSTITUIÇÃO, QUE ATUALMENTE MANTÉM O PROGRAMA FORÇAS NO ESPORTE (PROFESP), ATENDENDO CERCA DE 150 CRIANÇAS E ADOLESCENTES, E QUE, A PARTIR DE 2026, RECEBERÁ MAIS DE 260 ALUNOS PARA OS CURSOS DE FORMAÇÃO.
A28: 13 | B28: DEFESA | C28: 23970012 | D28: INDIVIDUAL | E28: INCLUSÃO - APROPRIAÇÃO | F28: 2397 | G28: HUGO LEAL | H28: DEPUTADO FEDERAL | I28: RJ | J28: PSD | K28: 52000 | L28: MINISTÉRIO DA DEFESA | M28: 52131 | N28: COMANDO DA MARINHA | O28: 05.152.6112.219D.0001 | P28: DEFESA NACIONAL | Q28: DEFESA NAVAL | R28: DEFESA NACIONAL | S28: ADEQUAÇÃO DE ATIVOS DE INFRAESTRUTURA DAS ORGANIZAÇÕES MILITARES | T28: NACIONAL | U28: NA | V28: NACIONAL | W28: F | X28: 4 | Y28: 90 | Z28: 0 | AA28: 6 | AB28: 1000 | AC28: 500000 | AD28: INVESTIMENTOS NA INFRAESTRUTURA DOS FUZILEIROS NAVAIS (MELHORIA DOS VESTIÁRIOS).
A29: 13 | B29: DEFESA | C29: 24460001 | D29: INDIVIDUAL | E29: INCLUSÃO - APROPRIAÇÃO | F29: 2446 | G29: JOÃO MAIA | H29: DEPUTADO FEDERAL | I29: RN | J29: PP | K29: 52000 | L29: MINISTÉRIO DA DEFESA | M29: 52931 | N29: FUNDO NAVAL | O29: 05.152.6112.21A0.0024 | P29: DEFESA NACIONAL | Q29: DEFESA NAVAL | R29: DEFESA NACIONAL | S29: APRESTAMENTO DAS FORÇAS - MANUTENÇÃO DA PRONTIDÃO E DA CAPACIDADE OPERATIVA | T29: NO ESTADO DO RIO GRANDE DO NORTE | U29: RN | V29: RIO GRANDE DO NORTE | W29: F | X29: 3 | Y29: 90 | Z29: 0 | AA29: 6 | AB29: 1000 | AC29: 300000 | AD29: A PRESENTE EMENDA PARLAMENTAR É DESTINADA À MANUTENÇÃO DE VIATURAS E REFORMA PREDIAL, OBJETIVANDO GARANTIR A PRONTIDÃO OPERATIVA DOS MEIOS EMPREGADOS NAS ATIVIDADES DO_x000D_ BATALHÃO, BEM COMO A READEQUAÇÃO DAS INSTALAÇÕES UTILIZADAS PELO EFETIVO.._x000D_ CNPJ : 00.394.502/0164-90
A30: 13 | B30: DEFESA | C30: 24680001 | D30: INDIVIDUAL | E30: INCLUSÃO - APROPRIAÇÃO | F30: 2468 | G30: LÍDICE DA MATA | H30: DEPUTADO FEDERAL | I30: BA | J30: PSB | K30: 52000 | L30: MINISTÉRIO DA DEFESA | M30: 52131 | N30: COMANDO DA MARINHA | O30: 05.301.0032.2E74.0029 | P30: DEFESA NACIONAL | Q30: ATENÇÃO BÁSICA | R30: PROGRAMA DE GESTÃO E MANUTENÇÃO DO PODER EXECUTIVO | S30: ESTRUTURAÇÃO E MODERNIZAÇÃO DE UNIDADES DE SAÚDE DAS FORÇAS ARMADAS | T30: NO ESTADO DA BAHIA | U30: BA | V30: BAHIA | W30: S | X30: 4 | Y30: 90 | Z30: 0 | AA30: 6 | AB30: 1000 | AC30: 120000 | AD30: HOSPITAL NAVAL DE SALVADOR - HNSA_x000D_ CNPJ: 00.394.502/0067-70_x000D_ _x000D_ CONTEMPLA A COMPRA DE EQUIPAMENTOS MÉDICOS PARA O SETOR DE ONCOLOGIA (INAUGURADO EM JANEIRO DE 2024), UTI, AMBULATÓRIO, LABORATÓRIO E CENTRO CIRÚRGICO, QUE AINDA NECESSITAM DE MATERIAL DE SAÚDE PARA SEU PLENO FUNCIONAMENTO. O HNSA É RESPONSÁVEL PELO ATENDIMENTO DE CERCA DE 16.000 USUÁRIOS ENTRE MILITARES E SEUS DEPENDENTES E, ALÉM DA SUA FUNÇÃO PRECÍPUA, TAMBÉM REALIZA AÇÕES CÍVICO-SOCIAIS EM PROL DE COMUNIDADES RIBEIRINHAS E CAIÇARAS, EM ÁREAS CARENTES. NA BUSCA DIUTURNA PELA MELHORIA DA QUALIDADE DO ATENDIMENTO PRESTADO AOS USUÁRIOS, FACE AO CRESCIMENTO CONTÍNUO DA DEMANDA DE ATENDIMENTO E DADA A IMPORTÂNCIA E CONTRIBUIÇÃO DO HOSPITAL PARA A SOCIEDADE, OBSERVA-SE A NECESSIDADE DE REALIZAÇÃO DE AQUISIÇÕES DE EQUIPAMENTOS DE SAÚDE PARA A VIABILIZAÇÃO DA EXPANSÃO DO ATENDIMENTO AO PÚBLICO, CONTRIBUINDO DIRETAMENTE COM O SISTEMA PÚBLICO DE SAÚDE LOCAL. _x000D_ O NÃO ATENDIMENTO DA DEMANDA SOLICITADA ELEVAM CUSTOS PARA ENCAMINHAMENTO A CLÍNICAS EXTERNAS E REDUZ A SEGURANÇA INDISPENSÁVEL AOS SERVIÇOS DE SAÚDE DESEMPENHADOS, TENDO EM VISTA QUE, OS REFERIDOS EQUIPAMENTOS PERMITEM QUE OS PROCEDIMENTOS E DIAGNÓSTICOS MÉDICOS SEJAM REALIZADOS COM A MÁXIMA PRESTEZA, HABILIDADE E EXCELÊNCIA, DENTRO DAS PRÓPRIAS INSTALAÇÕES DO HNSA.
A31: 13 | B31: DEFESA | C31: 24680003 | D31: INDIVIDUAL | E31: INCLUSÃO - APROPRIAÇÃO | F31: 2468 | G31: LÍDICE DA MATA | H31: DEPUTADO FEDERAL | I31: BA | J31: PSB | K31: 52000 | L31: MINISTÉRIO DA DEFESA | M31: 52121 | N31: COMANDO DO EXÉRCITO | O31: 05.153.6112.219D.0029 | P31: DEFESA NACIONAL | Q31: DEFESA TERRESTRE | R31: DEFESA NACIONAL | S31: ADEQUAÇÃO DE ATIVOS DE INFRAESTRUTURA DAS ORGANIZAÇÕES MILITARES | T31: NO ESTADO DA BAHIA | U31: BA | V31: BAHIA | W31: F | X31: 4 | Y31: 90 | Z31: 0 | AA31: 6 | AB31: 1000 | AC31: 120000 | AD31: ADEQUAÇÃO DE INSTALAÇÕES PARA ACOMODAR AS NOVAS RECRUTAS DO SERVIÇO MILITAR INICIAL FEMININO NA ESCOLA DE SAÚDE E FORMAÇÃO_x000D_ COMPLEMENTAR DO EXÉRCITO, COLÉGIO MILITAR DE SALVADOR, 6º BATALHÃO DE POLÍCIA DO EXÉRCITO E COMANDO DA 6ª REGIÃO MILITAR. | AE31: ESFCEx/CMS | AF31: Adequação de instalações SMIF
A32: 13 | B32: DEFESA | C32: 24680023 | D32: INDIVIDUAL | E32: INCLUSÃO - APROPRIAÇÃO | F32: 2468 | G32: LÍDICE DA MATA | H32: DEPUTADO FEDERAL | I32: BA | J32: PSB | K32: 52000 | L32: MINISTÉRIO DA DEFESA | M32: 52101 | N32: MINISTÉRIO DA DEFESA - ADMINISTRAÇÃO DIRETA | O32: 05.244.6111.21I8.0029 | P32: DEFESA NACIONAL | Q32: ASSISTÊNCIA COMUNITÁRIA | R32: COOPERAÇÃO DA DEFESA PARA O DESENVOLVIMENTO NACIONAL | S32: APOIO A PROJETOS SOCIAIS, EDUCACIONAIS E DE QUALIFICAÇÃO PROFISSIONAL | T32: NO ESTADO DA BAHIA | U32: BA | V32: BAHIA | W32: F | X32: 3 | Y32: 90 | Z32: 0 | AA32: 6 | AB32: 1000 | AC32: 100000 | AD32: O PROGRAMA FORÇAS NO ESPORTE (PROFESP) E O PROJETO JOÃO DO PULO (PJP) SÃO AÇÕES SOCIAIS CONDUZIDAS_x000D_ PELO MINISTÉRIO DA DEFESA (MD) E DESENVOLVIDAS POR INTERMÉDIO DA MARINHA DO BRASIL, DO EXÉRCITO BRASILEIRO_x000D_ E DA FORÇA AÉREA BRASILEIRA. ESSES PROJETOS PODEM CONTAR COM A PARCERIA DOS MINISTÉRIOS DOS DIREITOS_x000D_ HUMANOS E DA CIDADANIA, DA EDUCAÇÃO, DO ESPORTE, DA JUSTIÇA E SEGURANÇA PÚBLICA, DO DESENVOLVIMENTO E_x000D_ ASSISTÊNCIA SOCIAL, FAMÍLIA E COMBATE À FOME E DA SECRETARIA-GERAL DA PRESIDÊNCIA DA REPÚBLICA, DENTRE_x000D_ OUTRAS PASTAS DO EXECUTIVO FEDERAL._x000D_ O PROFESP E O PJP ATENDEM ATUALMENTE 11.479 BENEFICIADOS APROXIMADAMENTE, MAS COM CAPACIDADE PARA_x000D_ ATENDER ATÉ 30.000 JOVENS E CRIANÇAS, NA FAIXA ETÁRIA DE 6 A 18 ANOS, BEM COMO PESSOAS COM DEFICIÊNCIA, EM_x000D_ MAIS DE 200 (DUZENTAS) ORGANIZAÇÕES MILITARES (OM) DAS TRÊS FORÇAS ARMADAS QUE, DE FORMA VOLUNTÁRIA,_x000D_ DISPONIBILIZAM SUAS INSTALAÇÕES PARA A EXECUÇÃO DE ATIVIDADES PLANEJADAS E ELABORADAS COM_x000D_ ACOMPANHAMENTO PEDAGÓGICO, ABRANGENDO TODAS AS UNIDADES DA FEDERAÇÃO, EM MAIS DE 120 (CENTO E VINTE)_x000D_ MUNICÍPIOS, ALCANÇANDO LONGÍNQUAS REGIÕES DO NOSSO TERRITÓRIO, COMO, POR EXEMPLO, ALGUMAS COMUNIDADES_x000D_ INDÍGENAS E OUTRAS NA LINHA DE FRONTEIRA (PELOTÕES ESPECIAIS DE FRONTEIRA)._x000D_ NESTE SENTIDO, MEDIANTE OS COMPROVADOS ÍNDICES DE EFICÁCIA ATINGIDOS PELO PROFESP E PJP E CONSOANTE À_x000D_ SUA EFICIENTE SISTEMÁTICA DE FUNCIONAMENTO, VISLUMBRA-SE A POSSIBILIDADE DE AUMENTAR O NÚMERO DE_x000D_ BENEFICIÁRIOS, COM O FORNECIMENTO DE ALIMENTAÇÃO ADEQUADA E REALIZAÇÃO DE ATIVIDADES DESPORTIVAS E_x000D_ ESCOLARES, NO CONTRATURNO ESCOLAR EM UM AMBIENTE SEGURO, BEM COMO GARANTIR A MANUTENÇÃO DA INFRAESTRUTURA_x000D_ DESPORTIVA NAS INSTALAÇÕES EM QUE O PROGRAMA/PROJETO EM PAUTA É DESENVOLVIDO._x000D_ O RECURSO DA EMENDA CONTRIBUIRÁ PARA O FORTALECIMENTO DA INICIATIVA VOLUNTÁRIA DOS COMANDANTES DE OM_x000D_ QUE DESENVOLVEM O PROFESP E PJP NO ESTADO DA BAHIA E UMA PARCERIA COM V. EXA. TORNAR-SE-Á UM FATOR_x000D_ _x000D_ DE FUNDAMENTAL IMPORTÂNCIA PARA O SUCESSO DO EMPREENDIMENTO EM PROL DOS BENEFICIADOS E DE SUAS FAMÍLIAS._x000D_ ESSES RECURSOS FINANCEIROS SERÃO APLICADOS DENTRO DAS SEGUINTES FINALIDADES:_x000D_ A) ALIMENTAÇÃO DOS BENEFICIADOS;_x000D_ B) AQUISIÇÃO DE UNIFORME E MATERIAL ESPORTIVO PARA OS PARTICIPANTES DO PROGRAMA/PROJETO;_x000D_ C) APOIO À REALIZAÇÃO DE ATIVIDADES EDUCACIONAIS ESPORTIVAS;_x000D_ D) CAPACITAÇÃO PEDAGÓGICA PARA OS PROFESSORES, COORDENADORES E MONITORES; E_x000D_ E) MELHORIA DA INFRAESTRUTURA DAS OM PARTICIPANTES EM PROL DO PROFESP/PJP.
A33: 13 | B33: DEFESA | C33: 24820008 | D33: INDIVIDUAL | E33: ACRÉSCIMO - APROPRIAÇÃO | F33: 2482 | G33: LUIZ FERNANDO FARIA | H33: DEPUTADO FEDERAL | I33: MG | J33: UNIÃO | K33: 52000 | L33: MINISTÉRIO DA DEFESA | M33: 52121 | N33: COMANDO DO EXÉRCITO | O33: 05.153.6112.21A0.0001 | P33: DEFESA NACIONAL | Q33: DEFESA TERRESTRE | R33: DEFESA NACIONAL | S33: APRESTAMENTO DAS FORÇAS - MANUTENÇÃO DA PRONTIDÃO E DA CAPACIDADE OPERATIVA | T33: NACIONAL | U33: NA | V33: NACIONAL | W33: F | X33: 4 | Y33: 90 | Z33: 0 | AA33: 6 | AB33: 1000 | AC33: 350000 | AD33: BENEFICIÁRIO PARA LANÇAMENTO NO SIOP - CNPJ: 00.394.452/0001-03_x000D_ APOIAR O TRANSPORTE DOS MILITARES DA UNIDADE EM MISSÕES E PARA A REALIZAÇÃO DE AÇÕES CÍVICO-SOCIAIS (ACISO) OU EM AÇÕES JUNTO À DEFESA CIVIL E ÀS AUTORIDADES CIVIS QUE NECESSITEM DE APOIO._x000D_ _x000D_ COMPANHIA DE COMANDO DA 4ª BRIGADA LEVE DE MONTANHA (CIA C/4ª BDA INF L MTH), NO MUNICÍPIO DE JUIZ DE FORA - MG. | AE33: Cia C/4ª Bda Inf L Mth | AF33: Vtr Adm tipo Van
A34: 13 | B34: DEFESA | C34: 24820009 | D34: INDIVIDUAL | E34: INCLUSÃO - APROPRIAÇÃO | F34: 2482 | G34: LUIZ FERNANDO FARIA | H34: DEPUTADO FEDERAL | I34: MG | J34: UNIÃO | K34: 52000 | L34: MINISTÉRIO DA DEFESA | M34: 52111 | N34: COMANDO DA AERONÁUTICA | O34: 05.122.0032.2000.0031 | P34: DEFESA NACIONAL | Q34: ADMINISTRAÇÃO GERAL | R34: PROGRAMA DE GESTÃO E MANUTENÇÃO DO PODER EXECUTIVO | S34: ADMINISTRAÇÃO DA UNIDADE | T34: NO ESTADO DE MINAS GERAIS | U34: MG | V34: MINAS GERAIS | W34: F | X34: 4 | Y34: 90 | Z34: 0 | AA34: 6 | AB34: 1000 | AC34: 300000 | AD34: "CNPJ PARA LANÇAMENTO NO SIOP: 00.394.429/0001-00 - COMANDO DA AERONÁUTICA_x000D_ OM BENEFICIADA: ESCOLA PRAPARATÓRIA DE CADETES DO AR_x000D_ OBJETO RESUMIDO: USINA FOTOVOLTAICA DE 300 KW DE POTÊNCIA._x000D_ JUSTIFICATIVA:_x000D_ A FORÇA AÉREA BRASILEIRA (FAB), COMO INSTITUIÇÃO DE ESTADO, ATUA, ININTERRUPTAMENTE, NA DEFESA DA PÁTRIA, NA MANUTENÇÃO DA SOBERANIA DO NOSSO ESPAÇO AÉREO, NA PROTEÇÃO DE NOSSAS FRONTEIRAS E NA INTEGRAÇÃO DO TERRITÓRIO NACIONAL._x000D_ ADEMAIS, SUBSIDIARIAMENTE, A FAB CUMPRE MISSÕES HUMANITÁRIAS E DE REPATRIAÇÃO DE NACIONAIS, DE TRANSPORTE DE ÓRGÃOS E TECIDOS, BEM COMO CONTRIBUI COM O DESENVOLVIMENTO TECNOLÓGICO, GERANDO EMPREGOS E RIQUEZAS AO PAÍS._x000D_ PELO EXPOSTO, PARA CONTRIBUIR COM A FAB NO CUMPRIMENTO DE SUA MISSÃO CONSTITUCIONAL EM BENEFÍCIO DA SOCIEDADE BRASILEIRA, É NECESSÁRIO O APOIO AOS PROJETOS E ATIVIDADES SUPRAMENCIONADOS COM O APORTE DE RECURSOS DE EMENDAS PARLAMENTARES NA LEI ORÇAMENTÁRIA ANUAL (LOA) DE 2026."
A35: 13 | B35: DEFESA | C35: 25170009 | D35: INDIVIDUAL | E35: INCLUSÃO - APROPRIAÇÃO | F35: 2517 | G35: VINICIUS CARVALHO | H35: DEPUTADO FEDERAL | I35: SP | J35: PL | K35: 52000 | L35: MINISTÉRIO DA DEFESA | M35: 52121 | N35: COMANDO DO EXÉRCITO | O35: 05.301.0032.2E74.3474 | P35: DEFESA NACIONAL | Q35: ATENÇÃO BÁSICA | R35: PROGRAMA DE GESTÃO E MANUTENÇÃO DO PODER EXECUTIVO | S35: ESTRUTURAÇÃO E MODERNIZAÇÃO DE UNIDADES DE SAÚDE DAS FORÇAS ARMADAS | T35: NO MUNICÍPIO DE CAMPINAS - SP | U35: SP | V35: CAMPINAS | W35: S | X35: 4 | Y35: 90 | Z35: 0 | AA35: 6 | AB35: 1000 | AC35: 450000 | AD35: BENEFICIÁRIO PARA LANÇAMENTO NO SIOP - CNPJ: 00.394.452/0001-03_x000D_ MELHORAR O APOIO EM SAÚDE PARA OS MILITARES, ALUNOS, DEPENDENTES E A COMUNIDADE LOCAL NO CASO DE TRANSPORTE DE PACIENTES._x000D_ _x000D_ ESCOLA PREPARATÓRIA DE CADETES DO EXÉRCITO (ESPCEX), NO MUNICÍPIO DE CAMPINAS - SP. | AE35: EsPCEx | AF35: Ambulância tipo “B” – Suporte básico
A36: 13 | B36: DEFESA | C36: 25170012 | D36: INDIVIDUAL | E36: ACRÉSCIMO - APROPRIAÇÃO | F36: 2517 | G36: VINICIUS CARVALHO | H36: DEPUTADO FEDERAL | I36: SP | J36: PL | K36: 52000 | L36: MINISTÉRIO DA DEFESA | M36: 52131 | N36: COMANDO DA MARINHA | O36: 05.152.6112.219D.0001 | P36: DEFESA NACIONAL | Q36: DEFESA NAVAL | R36: DEFESA NACIONAL | S36: ADEQUAÇÃO DE ATIVOS DE INFRAESTRUTURA DAS ORGANIZAÇÕES MILITARES | T36: NACIONAL | U36: NA | V36: NACIONAL | W36: F | X36: 4 | Y36: 90 | Z36: 0 | AA36: 6 | AB36: 1000 | AC36: 400000 | AD36: BASE DE FUZILEIROS NAVAIS DA ILHA DAS FLORES - BFNIF_x000D_ CNPJ: 00.394.502/0344-72_x000D_ _x000D_ AS CRIANÇAS E JOVENS DO PROFESP UTILIZAM DIARIAMENTE A ESTRUTURA DO COMPLEXO AQUÁTICO DO CNIF PARA PRÁTICA DOS ESPORTES AQUÁTICOS (NATAÇÃO, PÓLO AQUÁTICO, ETC...) E RECREAÇÃO, CONTRIBUINDO PARA O DESENVOLVIMENTO DAS HABILIDADES MOTORAS, COGNITIVAS E SOCIAIS DOS ALUNOS. ESTE REFERIDO PROJETO ABRANGE A INSTALAÇÃO DE ÁGUA TÉRMICA, COBERTURA NA PISCINA E RAMPA PARA ACESSO DE PCD.
A37: 13 | B37: DEFESA | C37: 26010011 | D37: INDIVIDUAL | E37: INCLUSÃO - APROPRIAÇÃO | F37: 2601 | G37: MÁRCIO MARINHO | H37: DEPUTADO FEDERAL | I37: BA | J37: REPUBLICANOS | K37: 52000 | L37: MINISTÉRIO DA DEFESA | M37: 52931 | N37: FUNDO NAVAL | O37: 05.122.0032.2000.0001 | P37: DEFESA NACIONAL | Q37: ADMINISTRAÇÃO GERAL | R37: PROGRAMA DE GESTÃO E MANUTENÇÃO DO PODER EXECUTIVO | S37: ADMINISTRAÇÃO DA UNIDADE | T37: NACIONAL | U37: NA | V37: NACIONAL | W37: F | X37: 4 | Y37: 90 | Z37: 0 | AA37: 6 | AB37: 1000 | AC37: 1000000 | AD37: A REFERIDA EMENDA VISA ATENDER O COMANDO DO 2º DISTRITO NAVAL, CNPJ 00.394.502/0027-83, NA AQUISIÇÃO DE EQUIPAMENTOS E OBRAS NECESSÁRIAS PARA INSTALAR UMA ESTAÇÃO DE TRANSMISSÃO DE RADIO FM.
A38: 13 | B38: DEFESA | C38: 26760004 | D38: INDIVIDUAL | E38: INCLUSÃO - APROPRIAÇÃO | F38: 2676 | G38: VINICIUS GURGEL | H38: DEPUTADO FEDERAL | I38: AP | J38: PL | K38: 52000 | L38: MINISTÉRIO DA DEFESA | M38: 52121 | N38: COMANDO DO EXÉRCITO | O38: 05.153.6112.219D.0016 | P38: DEFESA NACIONAL | Q38: DEFESA TERRESTRE | R38: DEFESA NACIONAL | S38: ADEQUAÇÃO DE ATIVOS DE INFRAESTRUTURA DAS ORGANIZAÇÕES MILITARES | T38: NO ESTADO DO AMAPÁ | U38: AP | V38: AMAPÁ | W38: F | X38: 4 | Y38: 90 | Z38: 0 | AA38: 6 | AB38: 1000 | AC38: 230000 | AD38: A EMENDA TEM POR OBJETIVO DESTINAR RECURSO PARA A AQUISIÇÃO DE EQUIPAMENTO DE ACADEMIA PARA A UNIDADE DO EXÉRCITO BRASILEIRO NO ESTADO DO AMAPÁ. A MEDIDA VISA APRIMORAR AS CONDIÇÕES DE TREINAMENTO FÍSICO E DE SAÚDE DOS MILITARES, FORTALECENDO A PRONTIDÃO OPERACIONAL E A QUALIDADE DE VIDA DO EFETIVO. | AE38: Cmdo 22ª Bda Inf Sl | AF38: Equipamentos para academia de musculação
A39: 13 | B39: DEFESA | C39: 27010003 | D39: INDIVIDUAL | E39: INCLUSÃO - APROPRIAÇÃO | F39: 2701 | G39: DOMINGOS NETO | H39: DEPUTADO FEDERAL | I39: CE | J39: PSD | K39: 52000 | L39: MINISTÉRIO DA DEFESA | M39: 52121 | N39: COMANDO DO EXÉRCITO | O39: 05.153.6112.21A0.0023 | P39: DEFESA NACIONAL | Q39: DEFESA TERRESTRE | R39: DEFESA NACIONAL | S39: APRESTAMENTO DAS FORÇAS - MANUTENÇÃO DA PRONTIDÃO E DA CAPACIDADE OPERATIVA | T39: NO ESTADO DO CEARÁ | U39: CE | V39: CEARÁ | W39: F | X39: 3 | Y39: 90 | Z39: 0 | AA39: 6 | AB39: 1000 | AC39: 50000 | AD39: A PRESENTE EMENDA VISA PROPORCIONAR MELHORES CONDIÇÕES PARA A PRÁTICA DE ATIVIDADES FÍSICAS DOS ALUNOS E MILITARES DO COLÉGIO MILITAR DE FORTALEZA, COM AQUISIÇÃO DE MESA DE TÊNIS DE MESA, MATERIAIS PARA ESGRIMA, FUTMESA, TABELAS DE BASQUETE, PEBOLIM, ENTRE OUTROS. | AE39: CMF | AF39: Material esportivo e de recreação
A40: 13 | B40: DEFESA | C40: 27010003 | D40: INDIVIDUAL | E40: INCLUSÃO - APROPRIAÇÃO | F40: 2701 | G40: DOMINGOS NETO | H40: DEPUTADO FEDERAL | I40: CE | J40: PSD | K40: 52000 | L40: MINISTÉRIO DA DEFESA | M40: 52121 | N40: COMANDO DO EXÉRCITO | O40: 05.153.6112.21A0.0023 | P40: DEFESA NACIONAL | Q40: DEFESA TERRESTRE | R40: DEFESA NACIONAL | S40: APRESTAMENTO DAS FORÇAS - MANUTENÇÃO DA PRONTIDÃO E DA CAPACIDADE OPERATIVA | T40: NO ESTADO DO CEARÁ | U40: CE | V40: CEARÁ | W40: F | X40: 4 | Y40: 90 | Z40: 0 | AA40: 6 | AB40: 1000 | AC40: 200000 | AD40: A PRESENTE EMENDA VISA PROPORCIONAR MELHORES CONDIÇÕES PARA A PRÁTICA DE ATIVIDADES FÍSICAS DOS ALUNOS E MILITARES DO COLÉGIO MILITAR DE FORTALEZA, COM AQUISIÇÃO DE MESA DE TÊNIS DE MESA, MATERIAIS PARA ESGRIMA, FUTMESA, TABELAS DE BASQUETE, PEBOLIM, ENTRE OUTROS. | AE40: CMF | AF40: Material esportivo e de recreação
...

Sheet 2025
A1: Setor (Cod) | B1: Setor | C1: Emenda | D1: Emenda (Modalidade) | E1: Emenda (Tipo) | F1: Autor (Cod) | G1: Autor | H1: Autor (Tipo) | I1: Autor (UF) | J1: Partido | K1: Órgão (Cod) | L1: Órgão | M1: UO (Cod) | N1: UO | O1: Funcional | P1: Função | Q1: Subfunção | R1: Programa | S1: Ação | T1: Subtítulo | U1: UF | V1: Localidade | W1: Esfera (Cod) | X1: GND (Cod) | Y1: Mod. Aplic. (Cod) | Z1: ID Uso (Cod) | AA1: Identificador Primário (Cod) | AB1: Fonte (Cod) | AC1: Valor Solicitado | AD1: Emenda (Justificativa) | AE1: OM | AF1: Objeto
A2: 13 | B2: DEFESA | C2: 12710006 | D2: INDIVIDUAL | E2: INCLUSÃO - APROPRIAÇÃO | F2: 1271 | G2: LUIZ COUTO | H2: DEPUTADO FEDERAL | I2: PB | J2: PT | K2: 52000 | L2: MINISTÉRIO DA DEFESA | M2: 52931 | N2: FUNDO NAVAL | O2: 05.125.6112.21BY.0001 | P2: DEFESA NACIONAL | Q2: NORMATIZAÇÃO E FISCALIZAÇÃO | R2: DEFESA NACIONAL | S2: FISCALIZAÇÃO DA NAVEGAÇÃO AQUAVIÁRIA | T2: NACIONAL | U2: NA | V2: NACIONAL | W2: F | X2: 4 | Y2: 90 | Z2: 0 | AA2: 6 | AB2: 1000 | AC2: 250000 | AD2: CAPITANIA DOS PORTOS DA PARAÍBA - CPPB_x000D_ CNPJ: 00394502/0037-55_x000D_ A PRESENTE PROPOSTA DE EMENDA VISA À AQUISIÇÃO DE VIATURA PARA REALIZAR AÇÕES DE FISCALIZAÇÃO DO TRÁFICO AQUAVIÁRIA E DE APOIO AO ENSINO PROFISSIONAL MARITO, PERMITINDO A CAPITANIA DOS PORTOS DA PARAÍBA REALIZAR EM TODA EXTENSÃO DO LITORAL PARAIBANO.
A3: 13 | B3: DEFESA | C3: 14070006 | D3: INDIVIDUAL | E3: INCLUSÃO - APROPRIAÇÃO | F3: 1407 | G3: ODAIR CUNHA | H3: DEPUTADO FEDERAL | I3: MG | J3: PT | K3: 52000 | L3: MINISTÉRIO DA DEFESA | M3: 52931 | N3: FUNDO NAVAL | O3: 05.125.6112.21BY.0031 | P3: DEFESA NACIONAL | Q3: NORMATIZAÇÃO E FISCALIZAÇÃO | R3: DEFESA NACIONAL | S3: FISCALIZAÇÃO DA NAVEGAÇÃO AQUAVIÁRIA | T3: NO ESTADO DE MINAS GERAIS | U3: MG | V3: MINAS GERAIS | W3: F | X3: 4 | Y3: 90 | Z3: 0 | AA3: 6 | AB3: 1000 | AC3: 400000 | AD3: A AQUISIÇÃO DE NOVOS MEIOS TAIS COMO VIATURAS PICK-UP, COM REBOQUE E MOTO AQUÁTICA (230 HP), COM CARRETINHA, AMPLIAM A_x000D_ POSSIBILIDADE DE ATUAÇÃO DA CFMG NOS SEUS MUNICÍPIOS DA ÁREA DE JURISDIÇÃO TRAZENDO BENEFÍCIOS PARA A SEGURANÇA DA NAVEGAÇÃO E SALVAGUARDA DA_x000D_ VIDA HUMANA DOS CIDADÃOS NO ESTADO DE MINAS GERAIS.
A4: 13 | B4: DEFESA | C4: 14510001 | D4: INDIVIDUAL | E4: INCLUSÃO - APROPRIAÇÃO | F4: 1451 | G4: VANDER LOUBET | H4: DEPUTADO FEDERAL | I4: MS | J4: PT | K4: 52000 | L4: MINISTÉRIO DA DEFESA | M4: 52131 | N4: COMANDO DA MARINHA | O4: 05.152.6112.219D.5259 | P4: DEFESA NACIONAL | Q4: DEFESA NAVAL | R4: DEFESA NACIONAL | S4: ADEQUAÇÃO DE ATIVOS DE INFRAESTRUTURA DAS ORGANIZAÇÕES MILITARES | T4: NO MUNICÍPIO DE PORTO MURTINHO - MS | U4: MS | V4: PORTO MURTINHO | W4: F | X4: 4 | Y4: 90 | Z4: 0 | AA4: 6 | AB4: 1000 | AC4: 300000 | AD4: REESTRUTURAÇÃO DE MODERNIZAÇÃO DA AGÊNCIA FLUVIAL DE PORTO MURTINHO - MS (6O. COMANDO DA MARINHA DO BRASIL - LADÁRIO - MS), 2 VEÍCULOS.
A5: 13 | B5: DEFESA | C5: 15270012 | D5: INDIVIDUAL | E5: INCLUSÃO - APROPRIAÇÃO | F5: 1527 | G5: CARLOS SAMPAIO | H5: DEPUTADO FEDERAL | I5: SP | J5: PSD | K5: 52000 | L5: MINISTÉRIO DA DEFESA | M5: 52111 | N5: COMANDO DA AERONÁUTICA | O5: 05.122.0032.2000.0035 | P5: DEFESA NACIONAL | Q5: ADMINISTRAÇÃO GERAL | R5: PROGRAMA DE GESTÃO E MANUTENÇÃO DO PODER EXECUTIVO | S5: ADMINISTRAÇÃO DA UNIDADE | T5: NO ESTADO DE SÃO PAULO | U5: SP | V5: SÃO PAULO | W5: F | X5: 4 | Y5: 99 | Z5: 0 | AA5: 6 | AB5: 1000 | AC5: 200000 | AD5: A PRESENTE EMENDA TEM POR OBJETIVO A LIBERAÇÃO DE RECURSOS FINANCEIROS PARA AQUISIÇÃO DE MATERIAL INSTITUCIONAL PARA A AERONÁUTICA NO ESTADO DE SÃO PAULO
A6: 13 | B6: DEFESA | C6: 15680018 | D6: INDIVIDUAL | E6: INCLUSÃO - APROPRIAÇÃO | F6: 1568 | G6: GILBERTO NASCIMENTO | H6: DEPUTADO FEDERAL | I6: SP | J6: PSD | K6: 52000 | L6: MINISTÉRIO DA DEFESA | M6: 52911 | N6: FUNDO AERONÁUTICO | O6: 05.364.6112.21GQ.0035 | P6: DEFESA NACIONAL | Q6: ENSINO SUPERIOR | R6: DEFESA NACIONAL | S6: FUNCIONAMENTO DOS ESTABELECIMENTOS DE ENSINO SUPERIOR MILITARES DO MINISTÉRIO DA DEFESA | T6: NO ESTADO DE SÃO PAULO | U6: SP | V6: SÃO PAULO | W6: F | X6: 3 | Y6: 90 | Z6: 0 | AA6: 6 | AB6: 1000 | AC6: 150000 | AD6: CNPJ PARA LANÇAMENTO NO SIOP: 00.394.429/0001-00 - COMANDO DA AERONÁUTICA_x000D_ UNIDADE BENEFICIADA: ACADEMIA DA FORÇA AÉREA - AFA_x000D_ OBJETO RESUMIDO: READEQUAÇÃO DE SEÇÕES ADMINISTRATIVAS DO CORPO DE CADETES.
A7: 13 | B7: DEFESA | C7: 15680019 | D7: INDIVIDUAL | E7: INCLUSÃO - APROPRIAÇÃO | F7: 1568 | G7: GILBERTO NASCIMENTO | H7: DEPUTADO FEDERAL | I7: SP | J7: PSD | K7: 52000 | L7: MINISTÉRIO DA DEFESA | M7: 52121 | N7: COMANDO DO EXÉRCITO | O7: 05.301.0032.2E74.3928 | P7: DEFESA NACIONAL | Q7: ATENÇÃO BÁSICA | R7: PROGRAMA DE GESTÃO E MANUTENÇÃO DO PODER EXECUTIVO | S7: ESTRUTURAÇÃO E MODERNIZAÇÃO DE UNIDADES DE SAÚDE DAS FORÇAS ARMADAS | T7: NO MUNICÍPIO DE SÃO PAULO - SP | U7: SP | V7: SÃO PAULO | W7: S | X7: 4 | Y7: 90 | Z7: 0 | AA7: 6 | AB7: 1000 | AC7: 580000 | AD7: BENEFICIÁRIO PARA LANÇAMENTO NO SIOP - CNPJ: 00.394.452/0001-03_x000D_ POSSIBILITAR A REALIZAÇÃO DE EXAME BEIRA-LEITO EM PACIENTES ACAMADOS NO HOSPITAL MILITAR DE ÁREA DE SÃO PAULO/SP, SENDO DE FUNDAMENTAL IMPORTÂNCIA PARA A CONTINUIDADE DO TRATAMENTO. | AE7: HMASP | AF7: Aquisição de aparelho de ecocardiograma de alta resolução, com transdutor adulto 3D, transdutor pediátrico 3D, fetal 2D, convexo 2D.
A8: 13 | B8: DEFESA | C8: 15680020 | D8: INDIVIDUAL | E8: ACRÉSCIMO - APROPRIAÇÃO | F8: 1568 | G8: GILBERTO NASCIMENTO | H8: DEPUTADO FEDERAL | I8: SP | J8: PSD | K8: 52000 | L8: MINISTÉRIO DA DEFESA | M8: 52133 | N8: SECRETARIA DA COMISSÃO INTERMINISTERIAL PARA OS RECURSOS DO MAR | O8: 05.571.6113.2345.0001 | P8: DEFESA NACIONAL | Q8: DESENVOLVIMENTO CIENTÍFICO | R8: OCEANO, ZONA COSTEIRA E ANTÁRTICA | S8: APOIO LOGÍSTICO À PESQUISA CIENTÍFICA NA ANTÁRTICA | T8: NACIONAL | U8: NA | V8: NACIONAL | W8: F | X8: 3 | Y8: 90 | Z8: 0 | AA8: 6 | AB8: 1000 | AC8: 300000 | AD8: SECRETARIA DA COMISSÃO INTERMINISTERIAL PARA OS RECURSOS DO MAR - SECIRM_x000D_ CNPJ: 00.394.502/0165-71_x000D_ _x000D_ PROVER APOIO E SUPORTE LOGÍSTICO ÀS ATIVIDADES CIENTÍFICAS BRASILEIRAS REALIZADAS NO CONTINENTE ANTÁRTICO, PELO PROGRAMA ANTÁRTICO BRASILEIRO (PROANTAR), CORROBORANDO COM A PRESENÇA DO ESTADO BRASILEIRO NA REALIZAÇÃO DE RENOMADAS PESQUISAS A BORDO DOS NAVIOS DA MARINHA DO BRASIL, NAS ESTAÇÃO ANTÁRTICA COMANDANTE FERRAZ E ACAMPAMENTOS NO CONTINENTE, NA PRODUÇÃO DE CONHECIMENTOS, INCENTIVO À PESQUISA E FOMENTO À PARTICIPAÇÃO DE PESQUISADORES E INSTITUIÇÕES NACIONAIS NA COMPREENSÃO DOS FENÔMENOS QUE ALI OCORREM E QUE TENHAM REPERCUSSÃO GLOBAL E, PRINCIPALMENTE, NO PAÍS.
A9: 13 | B9: DEFESA | C9: 15680020 | D9: INDIVIDUAL | E9: ACRÉSCIMO - APROPRIAÇÃO | F9: 1568 | G9: GILBERTO NASCIMENTO | H9: DEPUTADO FEDERAL | I9: SP | J9: PSD | K9: 52000 | L9: MINISTÉRIO DA DEFESA | M9: 52133 | N9: SECRETARIA DA COMISSÃO INTERMINISTERIAL PARA OS RECURSOS DO MAR | O9: 05.571.6113.2345.0001 | P9: DEFESA NACIONAL | Q9: DESENVOLVIMENTO CIENTÍFICO | R9: OCEANO, ZONA COSTEIRA E ANTÁRTICA | S9: APOIO LOGÍSTICO À PESQUISA CIENTÍFICA NA ANTÁRTICA | T9: NACIONAL | U9: NA | V9: NACIONAL | W9: F | X9: 4 | Y9: 90 | Z9: 0 | AA9: 6 | AB9: 1000 | AC9: 100000 | AD9: SECRETARIA DA COMISSÃO INTERMINISTERIAL PARA OS RECURSOS DO MAR - SECIRM_x000D_ CNPJ: 00.394.502/0165-71_x000D_ _x000D_ PROVER APOIO E SUPORTE LOGÍSTICO ÀS ATIVIDADES CIENTÍFICAS BRASILEIRAS REALIZADAS NO CONTINENTE ANTÁRTICO, PELO PROGRAMA ANTÁRTICO BRASILEIRO (PROANTAR), CORROBORANDO COM A PRESENÇA DO ESTADO BRASILEIRO NA REALIZAÇÃO DE RENOMADAS PESQUISAS A BORDO DOS NAVIOS DA MARINHA DO BRASIL, NAS ESTAÇÃO ANTÁRTICA COMANDANTE FERRAZ E ACAMPAMENTOS NO CONTINENTE, NA PRODUÇÃO DE CONHECIMENTOS, INCENTIVO À PESQUISA E FOMENTO À PARTICIPAÇÃO DE PESQUISADORES E INSTITUIÇÕES NACIONAIS NA COMPREENSÃO DOS FENÔMENOS QUE ALI OCORREM E QUE TENHAM REPERCUSSÃO GLOBAL E, PRINCIPALMENTE, NO PAÍS.
A10: 13 | B10: DEFESA | C10: 16190006 | D10: INDIVIDUAL | E10: INCLUSÃO - APROPRIAÇÃO | F10: 1619 | G10: ÁTILA LINS | H10: DEPUTADO FEDERAL | I10: AM | J10: PSD | K10: 52000 | L10: MINISTÉRIO DA DEFESA | M10: 52931 | N10: FUNDO NAVAL | O10: 05.152.6112.21A0.0013 | P10: DEFESA NACIONAL | Q10: DEFESA NAVAL | R10: DEFESA NACIONAL | S10: APRESTAMENTO DAS FORÇAS - MANUTENÇÃO DA PRONTIDÃO E DA CAPACIDADE OPERATIVA | T10: NO ESTADO DO AMAZONAS | U10: AM | V10: AMAZONAS | W10: F | X10: 3 | Y10: 90 | Z10: 0 | AA10: 6 | AB10: 1000 | AC10: 500000 | AD10: RECUPERAÇÃO DO TELHADO DO PRÉDIO DA DIVISÃO DE ENSINO PROFISSIONAL MARÍTIMO DA CFT, QUE ENCONTRA-SE EM ESTADO AVANÇADO DE DETERIORAÇÃO. DESSA FORMA, TAIS INVESTIMENTOS NA INFRAESTRUTURA DA ORGANIZAÇÃO MILITAR CONTRIBUIRÃO PARA MELHORAR OS SERVIÇOS À POPULAÇÃO, FACILITARÃO AS MANOBRAS DE LANÇAMENTO DAS EMBARCAÇÕES EMPREGADAS NOS CURSOS DO ENSINO PROFISSIONAL MARÍTIMO E NAS INSPEÇÕES NAVAIS, PARTICULARMENTE NO PERÍODO DE SECA.
A11: 13 | B11: DEFESA | C11: 18670012 | D11: INDIVIDUAL | E11: ACRÉSCIMO - APROPRIAÇÃO | F11: 1867 | G11: LUIZ CARLOS HAULY | H11: DEPUTADO FEDERAL | I11: PR | J11: PODE | K11: 52000 | L11: MINISTÉRIO DA DEFESA | M11: 52932 | N11: FUNDO DE DESENVOLVIMENTO DO ENSINO PROFISSIONAL MARÍTIMO | O11: 05.363.6111.2510.0001 | P11: DEFESA NACIONAL | Q11: ENSINO PROFISSIONAL | R11: COOPERAÇÃO DA DEFESA PARA O DESENVOLVIMENTO NACIONAL | S11: PRESTAÇÃO DE ENSINO PROFISSIONAL MARÍTIMO | T11: NACIONAL | U11: NA | V11: NACIONAL | W11: F | X11: 4 | Y11: 90 | Z11: 0 | AA11: 6 | AB11: 1000 | AC11: 150000 | AD11: DELEGACIA FLUVIAL DE GUAÍRA - DELGUAIRA_x000D_ CNPJ: 00.394.502/0349-87_x000D_ _x000D_ A DELEGACIA FLUVIAL DE GUAÍRA POSSUI UMA ÁREA DE JURISDIÇÃO QUE ABRANGE 166 MUNICÍPIOS DO NORTE E DO OESTE DO ESTADO DO PARANÁ E TEM COMO PRINCIPAIS MALHAS HÍDRICAS OS RIOS PARANÁ, PARANAPANEMA, TIBAGI, IVAÍ E PIQUIRI, ALÉM DO LAGO IGAPÓ, EM LONDRINA. SÃO REALIZADOS, EM MÉDIA, 5 CURSOS ESPECIAIS PARA TRIPULANTES DO SERVIÇO PÚBLICO (ETSP), EM QUE SE FAZ NECESSÁRIA AULAS PRÁTICAS SOBRE CONDUÇÃO DE MOTO AQUÁTICA, COM A FORMAÇÃO DE CERCA DE 150 ALUNOS/ANO. ATUALMENTE, A DELEGACIA POSSUI DUAS MOTO AQUÁTICAS, JÁ BASTANTE USADAS, PARA EMPREGO TANTO EM AÇÕES DE FISCALIZAÇÃO, QUANTO DE INSTRUÇÃO E BUSCA E SALVAMENTO. A AQUISIÇÃO DE UMA NOVA EMBARCAÇÃO AMPLIARIA A CAPACIDADE DE ATENDIMENTO AOS CURSOS PROGRAMADOS, BEM COMO ÀS AÇÕES DE FISCALIZAÇÃO DO TRÁFEGO AQUAVIÁRIO E BUSCA E SALVAMENTO NA GRANDE MALHA HÍDRICA PRESENTE NA JURISDIÇÃO DA DELEGACIA FLUVIAL DE GUAÍRA.
A12: 13 | B12: DEFESA | C12: 18670014 | D12: INDIVIDUAL | E12: ACRÉSCIMO - APROPRIAÇÃO | F12: 1867 | G12: LUIZ CARLOS HAULY | H12: DEPUTADO FEDERAL | I12: PR | J12: PODE | K12: 52000 | L12: MINISTÉRIO DA DEFESA | M12: 52931 | N12: FUNDO NAVAL | O12: 05.125.6112.21BY.0001 | P12: DEFESA NACIONAL | Q12: NORMATIZAÇÃO E FISCALIZAÇÃO | R12: DEFESA NACIONAL | S12: FISCALIZAÇÃO DA NAVEGAÇÃO AQUAVIÁRIA | T12: NACIONAL | U12: NA | V12: NACIONAL | W12: F | X12: 4 | Y12: 90 | Z12: 0 | AA12: 6 | AB12: 1000 | AC12: 350000 | AD12: DELEGACIA FLUVIAL DE GUAÍRA - DELGUAIRA_x000D_ CNPJ: 00.394.502/0349-87_x000D_ _x000D_ A VIATURA VISA ATENDER A DEMANDA DE TRABALHO NA ÁREA DE JURISDIÇÃO DA DELEGACIA FLUVIAL GUAÍRA, QUE ABRANGE 166 MUNICÍPIOS DO NORTE E DO OESTE DO ESTADO DO PARANÁ E TEM COMO PRINCIPAIS MALHAS HÍDRICAS OS RIOS PARANÁ, PARANAPANEMA, TIBAGI, IVAÍ E PIQUIRI, ALÉM DO LAGO IGAPÓ, EM LONDRINA. TAMBÉM, CABE DESTACAR QUE A AQUISIÇÃO DE UMA VIATURA NOVA, ALÉM DE PROVER UM MELHOR ATENDIMENTO À COMUNIDADE NÁUTICA LOCAL, CONTRIBUIRÁ COM A RENOVAÇÃO DA FROTA ATUAL, COMPOSTA POR VEÍCULOS COM ALTA QUILOMETRAGEM, QUE EXIGEM GASTOS EXPRESSIVOS DE MANUTENÇÃO E QUE ENCONTRAM-SE COM A VIDA ÚTIL VENCIDA, EM VIRTUDE DOS DESLOCAMENTOS CONSTANTES PARA O POSTO AVANÇADO EM LONDRINA.
